Workbook
Name aaa: #REF!
Name aaa: #REF!
Name aaa: #REF!
Name aaa: #REF!
Name aaa: #REF!
Name aaa: #REF!
Name aaa: #REF!
Name aaaaa: #REF!
Name aaaaa: #REF!
Name aaaaa: #REF!
Name aaaaa: #REF!
Name aaaaa: #REF!
Name aaaaa: #REF!
Name aaaaa: #REF!
Name ADMINISTRAÇÃO: #REF!
Name ADMINISTRAÇÃO: #REF!
Name ADMINISTRAÇÃO: #REF!
Name ADMINISTRAÇÃO: #REF!
Name ATC: #REF!
Name ATC: #REF!
Name BANCO1: #REF!
Name BANCO1: #REF!
Name BANCO1: #REF!
Name BANCO1: #REF!
Name BANCO1: #REF!
Name BANCO1: #REF!
Name BANCO1: #REF!
Name BANCO2: #REF!
Name BANCO2: #REF!
Name BANCO2: #REF!
Name BANCO2: #REF!
Name BANCO2: #REF!
Name BANCO2: #REF!
Name BANCO2: #REF!
Name BANCO3: #REF!
Name BANCO3: #REF!
Name BANCO3: #REF!
Name BANCO3: #REF!
Name BANCO3: #REF!
Name BANCO3: #REF!
Name BANCO3: #REF!
Name BANCO4: #REF!
Name BANCO4: #REF!
Name BANCO4: #REF!
Name BANCO4: #REF!
Name BANCO4: #REF!
Name BANCO4: #REF!
Name BASE: OFFSET(#REF!,0,0,COUNTA(#REF!)+1,5)
Name BASE: OFFSET(#REF!,0,0,COUNTA(#REF!)+1,5)
Name BASE: OFFSET(#REF!,0,0,COUNTA(#REF!)+1,5)
Name BASE: OFFSET(#REF!,0,0,COUNTA(#REF!)+1,5)
Name BASE: OFFSET(#REF!,0,0,COUNTA(#REF!)+1,5)
Name BASE: OFFSET(#REF!,0,0,COUNTA(#REF!)+1,5)
Name BASE: OFFSET(#REF!,0,0,COUNTA(#REF!)+1,5)
Name CAUX2: OFFSET(#REF!,0,0,COUNTA(#REF!)+1,1)
Name CAUX2: OFFSET(#REF!,0,0,COUNTA(#REF!)+1,1)
Name CAUX2: OFFSET(#REF!,0,0,COUNTA(#REF!)+1,1)
Name CAUX2: OFFSET(#REF!,0,0,COUNTA(#REF!)+1,1)
Name CAUX2: OFFSET(#REF!,0,0,COUNTA(#REF!)+1,1)
Name CAUX2: OFFSET(#REF!,0,0,COUNTA(#REF!)+1,1)

Sheet Quadro de Areas
A2: QUADRO DE AREAS EQUIVALENTES | L2: QUADRO DE AREAS PRIVATIVAS
A3: BLOCO 01 | B3: TERREO | E3: Área Coberta - Fechada | F3: 1 | G3: 1 | H3: =133.91-H4-H5 -> 62.72 | I3: =F3*1*H3 -> 62.72 | J3: =F3*H3*G3 -> 62.72 | L3: 101 | M3: 1 | N3: 62.03 | O3: =N3*M3 -> 62.03
E4: Área Coberta - Fechada - Caixas + DML + Gerador + A. Cam. + Casa de Maq | F4: 1 | G4: 0.5 | H4: =6.4+3.08+4.26 -> 13.74 | I4: =F4*1*H4 -> 13.74 | J4: =F4*H4*G4 -> 6.87 | L4: 102 | M4: 1 | N4: 62.07 | O4: =N4*M4 -> 62.07
E5: Área Coberta - Fechada - Garagem | F5: 1 | G5: 0.5 | H5: 57.45 | I5: =F5*1*H5 -> 57.45 | J5: =F5*H5*G5 -> 28.725 | L5: 201 a 401 | M5: 3 | N5: =45.25+9.78 -> 55.03 | O5: =N5*M5 -> 165.09
E6: Área Descoberta - Aberta | F6: 1 | G6: 0.25 | H6: 8.62 | J6: =F6*H6*G6 -> 2.155 | L6: 202 a 402 | M6: 3 | N6: =45.36+9.79 -> 55.15 | O6: =N6*M6 -> 165.45
B7: 1º PAVIMENTO | E7: Área Coberta - Fechada | F7: 1 | G7: 1 | H7: =131.58-H8 -> 114.67 | I7: =F7*1*H7 -> 114.67 | J7: =F7*H7*G7 -> 114.67 | L7: 501 | M7: 1 | N7: 118.74 | O7: =N7*M7 -> 118.74
E8: Área Coberta - Aberta | F8: 1 | G8: 1 | H8: 16.91 | I8: =F8*1*H8 -> 16.91 | J8: =F8*H8*G8 -> 16.91 | L8: 502 | M8: 1 | N8: 118.08 | O8: =N8*M8 -> 118.08
E9: Área Descoberta - Aberta - Terraço | F9: 1 | G9: 0.5 | H9: 13.33 | J9: =F9*H9*G9 -> 6.665 | L9: TOTAL GERAL: | O9: =SUM(O3:O8) -> 691.46
B10: 2 ao 4º PAVIMENTO | E10: Área Coberta - Fechada | F10: 3 | G10: 1 | H10: =131.58-H11 -> 120.06 | I10: =F10*1*H10 -> 360.18 | J10: =F10*H10*G10 -> 360.18
E11: Área Coberta - Aberta | F11: 3 | G11: 1 | H11: 11.52 | I11: =F11*1*H11 -> 34.56 | J11: =F11*H11*G11 -> 34.56
B12: 5º PAVIMENTO | E12: Área Coberta - Fechada | F12: 1 | G12: 1 | H12: =131.58-H13 -> 114.68 | I12: =F12*1*H12 -> 114.68 | J12: =F12*H12*G12 -> 114.68
E13: Área Coberta - Aberta | F13: 1 | G13: 1 | H13: 16.9 | I13: =F13*1*H13 -> 16.9 | J13: =F13*H13*G13 -> 16.9
B14: 6º PAVIMENTO | E14: Área Coberta - Fechada | F14: 1 | G14: 1 | H14: =87.37-H15 -> 87.37 | I14: =F14*1*H14 -> 87.37 | J14: =F14*H14*G14 -> 87.37
E15: Área Coberta - Aberta | F15: 1 | G15: 1 | I15: =F15*1*H15 -> 0 | J15: =F15*H15*G15 -> 0
B16: COBERTURA | E16: Área Coberta - Fechada | F16: 1 | G16: 1 | H16: =22.94-H17 -> 22.94 | I16: =F16*1*H16 -> 22.94 | J16: =F16*H16*G16 -> 22.94
E17: Área Descoberta - Aberta | F17: 1 | G17: 0.5 | I17: =F17*1*H17 -> 0 | J17: =F17*H17*G17 -> 0
B18: TELHADO | E18: Área Coberta - Fechada | F18: 1 | G18: 0.5 | I18: =F18*1*H18 -> 0 | J18: =F18*H18*G18 -> 0
E19: Área Descoberta - Aberta | F19: 1 | G19: 0.25 | H19: 51.26 | J19: =F19*H19*G19 -> 12.815
A20: TOTAL GERAL: | I20: =SUM(I3:I19) -> 902.12 | J20: =SUM(J3:J19) -> 888.16

Sheet 02. Orçamento RASO
E1: PLANILHA ORÇAMENTÁRIA DETALHADA | K1: formulado | L1: PRAZO (meses)
L2: 8
K4: % DISTR
F5: CATEGORIA | G5: UNIDADE | H5: QTD. | I5: QTD. TOTAL | J5: VALOR | K5: 1 | L5: TOTAL | O5: VALOR SEM % DISTR
B7: CUSTO RASO | L7: =SUM(L9+L177) -> 3655161.1 | M7: =L7/$L$7 -> 1 | N7: =P7=L7 -> FALSE | O7: =SUM(O10:O819) -> 3261117 | P7: =O7*K5 -> 3261117
B8: 0 | C8: 0 | D8: 0 | E8: 0 | G8: 0 | H8: 0 | J8: =IFERROR(IF(K8<>0,K8*$K$5,0),0) -> 0 | M8: =L8/$L$7 -> 0
A9: =LEN(C9) -> 1 | C9: I | D9: DESPESAS INDIRETAS | L9: =SUMIF(A10:A176,3,L10:L176) -> 198955.94 | M9: =L9/$L$7 -> 0.05443151 | O9: =IF(I9<>0,I9*H9*K9,) -> 0 | R9: =IF(J9<>0,J9/1.03-K9,0) -> 0
A10: =LEN(C10) -> 3 | C10: 01. | D10: SERVIÇOS TÉCNICOS E PRELIMINARES | L10: =SUMIF(A11:A24,4,L11:L24) -> 1 | M10: =L10/$L$7 -> 2.7358575e-07 | O10: =IF(I10<>0,I10*H10*K10,) -> 0 | R10: =IF(J10<>0,J10/1.03-K10,0) -> 0
A11: =LEN(C11) -> 0 | J11: =IFERROR(IF(K11<>0,K11*$K$5,0),0) -> 0 | K11: =IF(A11=0,VLOOKUP(D11,'03. Insumos'!A:F,4,0),"") -> #N/A | M11: =L11/$L$7 -> 0 | O11: =IF(I11<>0,I11*H11*K11,) -> 0 | R11: =IF(J11<>0,J11/1.03-K11,0) -> 0
A12: =LEN(C12) -> 4 | C12: 01.1 | D12: Serviços Preliminares | K12: =IF(A12=0,VLOOKUP(D12,'03. Insumos'!A:F,4,0),"") | L12: =SUMIF(A13:A14,6,L13:L14) -> 0 | M12: =L12/$L$7 -> 0 | O12: =IF(I12<>0,I12*H12*K12,) -> 0 | R12: =IF(J12<>0,J12/1.03-K12,0) -> 0
A13: =LEN(C13) -> 6 | C13: 01.1.1 | D13: Placa de Obra | K13: =IF(A13=0,VLOOKUP(D13,'03. Insumos'!A:F,4,0),"") | M13: =L13/$L$7 -> 0 | O13: =IF(I13<>0,I13*H13*K13,) -> 0 | R13: =IF(J13<>0,J13/1.03-K13,0) -> 0
A14: =LEN(C14) -> 0 | D14: 01.01.0001 | E14: =VLOOKUP(D14,'03. Insumos'!A:D,2,0) -> Placa de Obra | G14: =VLOOKUP(D14,'03. Insumos'!A:F,3,0) -> vb | H14: 1 | J14: =IFERROR(IF(K14<>0,K14*$K$5,0),0) -> 1 | K14: =IF(A14=0,VLOOKUP(D14,'03. Insumos'!A:F,4,0),"") -> 1 | L14: =H14*J14*I14 -> 0 | M14: =L14/$L$7 -> 0 | O14: =IF(I14<>0,I14*H14*K14,) -> 0 | R14: =IF(J14<>0,J14/1.03-K14,0) -> -0.029126214
A15: =LEN(C15) -> 4 | C15: 01.2 | D15: Serviços Técnicos | K15: =IF(A15=0,VLOOKUP(D15,'03. Insumos'!A:F,4,0),"") | L15: =SUMIF(A16:A24,6,L16:L24) -> 1 | M15: =L15/$L$7 -> 2.7358575e-07 | O15: =IF(I15<>0,I15*H15*K15,) -> 0 | R15: =IF(J15<>0,J15/1.03-K15,0) -> 0
A16: =LEN(C16) -> 6 | C16: 01.2.1 | D16: Controle Tecnológico | K16: =IF(A16=0,VLOOKUP(D16,'03. Insumos'!A:F,4,0),"") | L16: =SUM(L17:L20) -> 0 | M16: =L16/$L$7 -> 0 | O16: =IF(I16<>0,I16*H16*K16,) -> 0 | R16: =IF(J16<>0,J16/1.03-K16,0) -> 0
A17: =LEN(C17) -> 0 | D17: 01.01.0105 | E17: =VLOOKUP(D17,'03. Insumos'!A:D,2,0) -> Controle Tecnológico - Ensaio compressão simples concreto NBR 7215 | G17: =VLOOKUP(D17,'03. Insumos'!A:F,3,0) -> cp | H17: 1 | J17: =IFERROR(IF(K17<>0,K17*$K$5,0),0) -> 12 | K17: =IF(A17=0,VLOOKUP(D17,'03. Insumos'!A:F,4,0),"") -> 12 | L17: =H17*J17*I17 -> 0 | M17: =L17/$L$7 -> 0 | O17: =IF(I17<>0,I17*H17*K17,) -> 0 | R17: =IF(J17<>0,J17/1.03-K17,0) -> -0.34951456
A18: =LEN(C18) -> 0 | D18: 01.01.0103 | E18: =VLOOKUP(D18,'03. Insumos'!A:D,2,0) -> Controle Tecnológico - Diária Moldador | G18: =VLOOKUP(D18,'03. Insumos'!A:F,3,0) -> dia | H18: 1 | J18: =IFERROR(IF(K18<>0,K18*$K$5,0),0) -> 225 | K18: =IF(A18=0,VLOOKUP(D18,'03. Insumos'!A:F,4,0),"") -> 225 | L18: =H18*J18*I18 -> 0 | M18: =L18/$L$7 -> 0 | O18: =IF(I18<>0,I18*H18*K18,) -> 0 | R18: =IF(J18<>0,J18/1.03-K18,0) -> -6.5533981
A19: =LEN(C19) -> 0 | D19: 01.01.0104 | E19: =VLOOKUP(D19,'03. Insumos'!A:D,2,0) -> Controle Tecnológico - Mobilização | G19: =VLOOKUP(D19,'03. Insumos'!A:F,3,0) -> uni | H19: 1 | J19: =IFERROR(IF(K19<>0,K19*$K$5,0),0) -> 155 | K19: =IF(A19=0,VLOOKUP(D19,'03. Insumos'!A:F,4,0),"") -> 155 | L19: =H19*J19*I19 -> 0 | M19: =L19/$L$7 -> 0 | O19: =IF(I19<>0,I19*H19*K19,) -> 0 | R19: =IF(J19<>0,J19/1.03-K19,0) -> -4.5145631
A20: =LEN(C20) -> 0 | D20: 01.01.0107 | E20: =VLOOKUP(D20,'03. Insumos'!A:D,2,0) -> Controle Tecnológico - Coleta de materiais na obra | G20: =VLOOKUP(D20,'03. Insumos'!A:F,3,0) -> uni | H20: 1 | J20: =IFERROR(IF(K20<>0,K20*$K$5,0),0) -> 155 | K20: =IF(A20=0,VLOOKUP(D20,'03. Insumos'!A:F,4,0),"") -> 155 | L20: =H20*J20*I20 -> 0 | M20: =L20/$L$7 -> 0 | O20: =IF(I20<>0,I20*H20*K20,) -> 0 | R20: =IF(J20<>0,J20/1.03-K20,0) -> -4.5145631
A21: =LEN(C21) -> 6 | C21: 01.2.2 | D21: Consultorias | K21: =IF(A21=0,VLOOKUP(D21,'03. Insumos'!A:F,4,0),"") | L21: =SUM(L22:L22) -> 0 | M21: =L21/$L$7 -> 0 | R21: =IF(J21<>0,J21/1.03-K21,0) -> 0
A22: =LEN(C22) -> 0 | D22: 01.01.0005 | E22: =VLOOKUP(D22,'03. Insumos'!A:D,2,0) -> Consultoria Estrutura | G22: =VLOOKUP(D22,'03. Insumos'!A:F,3,0) -> mês | H22: 1 | J22: =IFERROR(IF(K22<>0,K22*$K$5,0),0) -> 3000 | K22: =IF(A22=0,VLOOKUP(D22,'03. Insumos'!A:F,4,0),"") -> 3000 | L22: =H22*J22*I22 -> 0 | M22: =L22/$L$7 -> 0 | O22: =IF(I22<>0,I22*H22*K22,) -> 0 | R22: =IF(J22<>0,J22/1.03-K22,0) -> -87.378641
A23: =LEN(C23) -> 6 | C23: 01.2.3 | D23: Seguro de Obra | K23: =IF(A23=0,VLOOKUP(D23,'03. Insumos'!A:F,4,0),"") | L23: =SUM(L24:L26) -> 1 | M23: =L23/$L$7 -> 2.7358575e-07 | R23: =IF(J23<>0,J23/1.03-K23,0) -> 0
A24: =LEN(C24) -> 0 | D24: 01.01.0713 | E24: =VLOOKUP(D24,'03. Insumos'!A:D,2,0) -> Seguro responsabilidade civil e cruzada | F24: SERV. ESP. | G24: =VLOOKUP(D24,'03. Insumos'!A:F,3,0) -> vb | H24: 1 | I24: 1 | J24: =IFERROR(IF(K24<>0,K24*$K$5,0),0) -> 1 | K24: =IF(A24=0,VLOOKUP(D24,'03. Insumos'!A:F,4,0),"") -> 1 | L24: =H24*J24*I24 -> 1 | M24: =L24/$L$7 -> 2.7358575e-07 | O24: =IF(I24<>0,I24*H24*K24,) -> 1 | R24: =IF(J24<>0,J24/1.03-K24,0) -> -0.029126214
A25: =LEN(C25) -> 0 | D25: 01.01.0714 | E25: =VLOOKUP(D25,'03. Insumos'!A:D,2,0) -> Seguro Performance Bond | G25: =VLOOKUP(D25,'03. Insumos'!A:F,3,0) -> vb | H25: 12 | J25: =IFERROR(IF(K25<>0,K25*$K$5,0),0) -> 1 | K25: =IF(A25=0,VLOOKUP(D25,'03. Insumos'!A:F,4,0),"") -> 1 | L25: =H25*J25*I25 -> 0 | M25: =L25/$L$7 -> 0
A26: =LEN(C26) -> 0 | D26: 01.01.0773 | E26: =VLOOKUP(D26,'03. Insumos'!A:D,2,0) -> Carta fiança (10% valor) | G26: =VLOOKUP(D26,'03. Insumos'!A:F,3,0) -> vb | H26: 1 | J26: =IFERROR(IF(K26<>0,K26*$K$5,0),0) -> 85135.685 | K26: =0.03*2837856.16 -> 85135.685 | L26: =H26*J26*I26 -> 0 | M26: =L26/$L$7 -> 0
A27: =LEN(C27) -> 3 | C27: 02. | D27: INSTALAÇÕES PROVISÓRIAS E CANTEIRO | L27: =SUMIF(A28:A49,4,L28:L49) -> 2139 | M27: =L27/$L$7 -> 0.00058519992 | O27: =IF(I27<>0,I27*H27*K27,) -> 0 | R27: =IF(J27<>0,J27/1.03-K27,0) -> 0
A28: =LEN(C28) -> 0 | J28: =IFERROR(IF(K28<>0,K28*$K$5,0),0) -> 0 | K28: =IF(A28=0,VLOOKUP(D28,'03. Insumos'!A:F,4,0),"") -> #N/A | M28: =L28/$L$7 -> 0 | O28: =IF(I28<>0,I28*H28*K28,) -> 0 | R28: =IF(J28<>0,J28/1.03-K28,0) -> 0
A29: =LEN(C29) -> 4 | C29: 02.1 | D29: Canteiro de Obras | K29: =IF(A29=0,VLOOKUP(D29,'03. Insumos'!A:F,4,0),"") | L29: =SUMIF(A30:A49,6,L30:L49) -> 2139 | M29: =L29/$L$7 -> 0.00058519992 | O29: =IF(I29<>0,I29*H29*K29,) -> 0 | R29: =IF(J29<>0,J29/1.03-K29,0) -> 0
A30: =LEN(C30) -> 6 | C30: 02.1.1 | D30: Barraco | K30: =IF(A30=0,VLOOKUP(D30,'03. Insumos'!A:F,4,0),"") | L30: =SUM(L31:L36) -> 0 | M30: =L30/$L$7 -> 0 | O30: =IF(I30<>0,I30*H30*K30,) -> 0 | R30: =IF(J30<>0,J30/1.03-K30,0) -> 0
A31: =LEN(C31) -> 0 | D31: 01.01.0717 | E31: =VLOOKUP(D31,'03. Insumos'!A:D,2,0) -> Barraco de Obra | G31: =VLOOKUP(D31,'03. Insumos'!A:F,3,0) -> vb | H31: 1 | J31: =IFERROR(IF(K31<>0,K31*$K$5,0),0) -> 45169.28 | K31: 45169.28 | L31: =H31*J31*I31 -> 0 | M31: =L31/$L$7 -> 0 | O31: =IF(I31<>0,I31*H31*K31,) -> 0 | R31: =IF(J31<>0,J31/1.03-K31,0) -> -1315.6101
A32: =LEN(C32) -> 0 | D32: 01.01.0716 | E32: =VLOOKUP(D32,'03. Insumos'!A:D,2,0) -> Mobiliário para barraco | G32: =VLOOKUP(D32,'03. Insumos'!A:F,3,0) -> vb | H32: 1 | J32: =IFERROR(IF(K32<>0,K32*$K$5,0),0) -> 20143.76 | K32: 20143.76 | L32: =H32*J32*I32 -> 0 | M32: =L32/$L$7 -> 0
A33: =LEN(C33) -> 0 | D33: 01.01.0767 | E33: =VLOOKUP(D33,'03. Insumos'!A:D,2,0) -> Módulo habitacional banheiro | G33: =VLOOKUP(D33,'03. Insumos'!A:F,3,0) -> mês | H33: 1 | J33: =IFERROR(IF(K33<>0,K33*$K$5,0),0) -> 620 | K33: =IF(A33=0,VLOOKUP(D33,'03. Insumos'!A:F,4,0),"") -> 620 | L33: =H33*J33*I33 -> 0 | M33: =L33/$L$7 -> 0
A34: =LEN(C34) -> 0 | D34: 01.01.0768 | E34: =VLOOKUP(D34,'03. Insumos'!A:D,2,0) -> Banheiro químico | G34: =VLOOKUP(D34,'03. Insumos'!A:F,3,0) -> mês | H34: 2 | J34: =IFERROR(IF(K34<>0,K34*$K$5,0),0) -> 700 | K34: =IF(A34=0,VLOOKUP(D34,'03. Insumos'!A:F,4,0),"") -> 700 | L34: =H34*J34*I34 -> 0 | M34: =L34/$L$7 -> 0
A35: =LEN(C35) -> 0 | D35: 01.01.0729 | E35: =VLOOKUP(D35,'03. Insumos'!A:D,2,0) -> Container marítimo 20 pés | G35: =VLOOKUP(D35,'03. Insumos'!A:F,3,0) -> unid | H35: 2 | J35: =IFERROR(IF(K35<>0,K35*$K$5,0),0) -> 500 | K35: =IF(A35=0,VLOOKUP(D35,'03. Insumos'!A:F,4,0),"") -> 500 | L35: =H35*J35*I35 -> 0 | M35: =L35/$L$7 -> 0
A36: =LEN(C36) -> 0 | D36: 01.01.0730 | E36: =VLOOKUP(D36,'03. Insumos'!A:D,2,0) -> Frete container marítimo | G36: =VLOOKUP(D36,'03. Insumos'!A:F,3,0) -> unid | H36: 1 | J36: =IFERROR(IF(K36<>0,K36*$K$5,0),0) -> 800 | K36: =IF(A36=0,VLOOKUP(D36,'03. Insumos'!A:F,4,0),"") -> 800 | L36: =H36*J36*I36 -> 0 | M36: =L36/$L$7 -> 0
A37: =LEN(C37) -> 6 | C37: 02.1.2 | D37: Isolamento área de trabalho | K37: =IF(A37=0,VLOOKUP(D37,'03. Insumos'!A:F,4,0),"") | L37: =SUM(L38:L38) -> 0 | M37: =L37/$L$7 -> 0 | O37: =IF(I37<>0,I37*H37*K37,) -> 0 | R37: =IF(J37<>0,J37/1.03-K37,0) -> 0
A38: =LEN(C38) -> 0 | D38: 01.01.0429 | E38: =VLOOKUP(D38,'03. Insumos'!A:D,2,0) -> Tapume metálico | G38: vb | H38: 1 | J38: =IFERROR(IF(K38<>0,K38*$K$5,0),0) -> 100 | K38: =IF(A38=0,VLOOKUP(D38,'03. Insumos'!A:F,4,0),"") -> 100 | L38: =H38*J38*I38 -> 0 | M38: =L38/$L$7 -> 0 | O38: =IF(I38<>0,I38*H38*K38,) -> 0 | R38: =IF(J38<>0,J38/1.03-K38,0) -> -2.9126214
A39: =LEN(C39) -> 6 | C39: 02.1.3 | D39: Instalações provisórias | K39: =IF(A39=0,VLOOKUP(D39,'03. Insumos'!A:F,4,0),"") | L39: =SUM(L40:L49) -> 2139 | M39: =L39/$L$7 -> 0.00058519992 | O39: =IF(I39<>0,I39*H39*K39,) -> 0 | R39: =IF(J39<>0,J39/1.03-K39,0) -> 0
A40: =LEN(C40) -> 0 | D40: 01.01.0424 | E40: =VLOOKUP(D40,'03. Insumos'!A:D,2,0) -> Cabo PP (2 x 2,5 mm) | F40: MAT CONSUMO | G40: =VLOOKUP(D40,'03. Insumos'!A:F,3,0) -> m | H40: 1 | I40: 200 | J40: =IFERROR(IF(K40<>0,K40*$K$5,0),0) -> 3.22 | K40: =IF(A40=0,VLOOKUP(D40,'03. Insumos'!A:F,4,0),"") -> 3.22 | L40: =H40*J40*I40 -> 644 | M40: =L40/$L$7 -> 0.00017618922 | O40: =IF(I40<>0,I40*H40*K40,) -> 644 | R40: =IF(J40<>0,J40/1.03-K40,0) -> -0.093786408
A41: =LEN(C41) -> 0 | D41: 01.01.0425 | E41: =VLOOKUP(D41,'03. Insumos'!A:D,2,0) -> Bocal para lâmpada | F41: MAT CONSUMO | G41: =VLOOKUP(D41,'03. Insumos'!A:F,3,0) -> unid | H41: 1 | I41: 10 | J41: =IFERROR(IF(K41<>0,K41*$K$5,0),0) -> 3.5 | K41: =IF(A41=0,VLOOKUP(D41,'03. Insumos'!A:F,4,0),"") -> 3.5 | L41: =H41*J41*I41 -> 35 | M41: =L41/$L$7 -> 9.5755012e-06
A42: =LEN(C42) -> 0 | D42: 01.01.0426 | E42: =VLOOKUP(D42,'03. Insumos'!A:D,2,0) -> Lâmpada | F42: MAT CONSUMO | G42: =VLOOKUP(D42,'03. Insumos'!A:F,3,0) -> unid | H42: 1 | I42: 20 | J42: =IFERROR(IF(K42<>0,K42*$K$5,0),0) -> 6 | K42: =IF(A42=0,VLOOKUP(D42,'03. Insumos'!A:F,4,0),"") -> 6 | L42: =H42*J42*I42 -> 120 | M42: =L42/$L$7 -> 3.283029e-05
...

Sheet 02. Orçamento - opção troca pis
E1: PLANILHA ORÇAMENTÁRIA DETALHADA | K1: formulado | L1: PRAZO (meses)
L2: 4
K4: % DISTR
F5: CATEGORIA | G5: UNIDADE | H5: QTD. | I5: QTD. TOTAL | J5: VALOR | K5: 1 | L5: TOTAL | O5: VALOR SEM % DISTR
B7: CUSTO TOTAL | L7: =SUM(L9+L191) -> 563357.81 | M7: =L7/$L$7 -> 1 | N7: =P7=L7 -> #VALUE! | O7: =SUM(O10:O628) -> #VALUE! | P7: =O7*K5 -> #VALUE!
B8: 0 | C8: 0 | D8: 0 | E8: 0 | G8: 0 | H8: 0 | J8: =IFERROR(IF(K8<>0,K8*$K$5,0),0) -> 0 | M8: =L8/$L$7 -> 0
A9: =LEN(C9) -> 1 | C9: I | D9: DESPESAS INDIRETAS | L9: =SUMIF(A10:A190,3,L10:L190) -> 81268.395 | M9: =L9/$L$7 -> 0.14425715 | O9: =IF(I9<>0,I9*H9*K9,) -> 0 | R9: =IF(J9<>0,J9/1.03-K9,0) -> 0
A10: =LEN(C10) -> 3 | C10: 01. | D10: SERVIÇOS TÉCNICOS E PRELIMINARES | L10: =SUMIF(A11:A27,4,L11:L27) -> 10002 | M10: =L10/$L$7 -> 0.017754258 | O10: =IF(I10<>0,I10*H10*K10,) -> 0 | R10: =IF(J10<>0,J10/1.03-K10,0) -> 0
A11: =LEN(C11) -> 4 | C11: 01.1 | D11: Serviços Preliminares | K11: =IF(A11=0,VLOOKUP(D11,'03. Insumos'!A:F,4,0),"") | L11: =SUMIF(A12:A15,6,L12:L15) -> 10002 | M11: =L11/$L$7 -> 0.017754258 | O11: =IF(I11<>0,I11*H11*K11,) -> 0 | R11: =IF(J11<>0,J11/1.03-K11,0) -> 0
A12: =LEN(C12) -> 6 | C12: 01.1.1 | D12: Serviços Preliminares | K12: =IF(A12=0,VLOOKUP(D12,'03. Insumos'!A:F,4,0),"") | L12: =SUM(L13:L15) -> 10002 | M12: =L12/$L$7 -> 0.017754258 | O12: =IF(I12<>0,I12*H12*K12,) -> 0 | R12: =IF(J12<>0,J12/1.03-K12,0) -> 0
A13: 0 | D13: 01.01.0713 | E13: =VLOOKUP(D13,'03. Insumos'!A:D,2,0) -> Seguro responsabilidade civil e cruzada | F13: FAT DIRETO | G13: =VLOOKUP(D13,'03. Insumos'!A:F,3,0) -> vb | H13: 1 | I13: 1 | J13: =IFERROR(IF(K13<>0,K13*$K$5,0),0) -> 1 | K13: =IF(A13=0,VLOOKUP(D13,'03. Insumos'!A:F,4,0),"") -> 1 | L13: =H13*J13*I13 -> 1 | M13: =L13/$L$7 -> 1.7750708e-06
A14: 0 | D14: 01.01.0001 | E14: =VLOOKUP(D14,'03. Insumos'!A:D,2,0) -> Placa de Obra | F14: RASA | G14: =VLOOKUP(D14,'03. Insumos'!A:F,3,0) -> vb | H14: 1 | I14: 1 | J14: =IFERROR(IF(K14<>0,K14*$K$5,0),0) -> 1 | K14: =IF(A14=0,VLOOKUP(D14,'03. Insumos'!A:F,4,0),"") -> 1 | L14: =H14*J14*I14 -> 1 | M14: =L14/$L$7 -> 1.7750708e-06
A15: =LEN(C15) -> 0 | D15: 01.01.1309 | E15: =VLOOKUP(D15,'03. Insumos'!A:D,2,0) -> Mestre De Obra | F15: RASA | G15: =VLOOKUP(D15,'03. Insumos'!A:F,3,0) -> mês | H15: 1 | I15: 1 | J15: =IFERROR(IF(K15<>0,K15*$K$5,0),0) -> 10000 | K15: =IF(A15=0,VLOOKUP(D15,'03. Insumos'!A:F,4,0),"") -> 10000 | L15: =H15*J15*I15 -> 10000 | M15: =L15/$L$7 -> 0.017750708 | O15: =IF(I15<>0,I15*H15*K15,) -> 10000 | R15: =IF(J15<>0,J15/1.03-K15,0) -> -291.26214
A16: =LEN(C16) -> 4 | C16: 01.2 | D16: Serviços Técnicos | K16: =IF(A16=0,VLOOKUP(D16,'03. Insumos'!A:F,4,0),"") | L16: =SUMIF(A17:A25,6,L17:L27) -> 0 | M16: =L16/$L$7 -> 0 | O16: =IF(I16<>0,I16*H16*K16,) -> 0 | R16: =IF(J16<>0,J16/1.03-K16,0) -> 0
A17: =LEN(C17) -> 6 | C17: 01.2.1 | D17: Controle Tecnológico | G17: m³ | K17: =IF(A17=0,VLOOKUP(D17,'03. Insumos'!A:F,4,0),"") | L17: =SUM(L18:L21) -> 0 | M17: =L17/$L$7 -> 0 | O17: =IF(I17<>0,I17*H17*K17,) -> 0 | R17: =IF(J17<>0,J17/1.03-K17,0) -> 0
A18: =LEN(C18) -> 0 | D18: 01.01.0105 | E18: =VLOOKUP(D18,'03. Insumos'!A:D,2,0) -> Controle Tecnológico - Ensaio compressão simples concreto NBR 7215 | F18: FAT DIRETO | G18: =VLOOKUP(D18,'03. Insumos'!A:F,3,0) -> cp | I18: 5 | J18: =IFERROR(IF(K18<>0,K18*$K$5,0),0) -> 12 | K18: =IF(A18=0,VLOOKUP(D18,'03. Insumos'!A:F,4,0),"") -> 12 | L18: =H18*J18*I18 -> 0 | M18: =L18/$L$7 -> 0 | O18: =IF(I18<>0,I18*H18*K18,) -> 0 | R18: =IF(J18<>0,J18/1.03-K18,0) -> -0.34951456
A19: =LEN(C19) -> 0 | D19: 01.01.0103 | E19: =VLOOKUP(D19,'03. Insumos'!A:D,2,0) -> Controle Tecnológico - Diária Moldador | F19: FAT DIRETO | G19: =VLOOKUP(D19,'03. Insumos'!A:F,3,0) -> dia | I19: 5 | J19: =IFERROR(IF(K19<>0,K19*$K$5,0),0) -> 225 | K19: =IF(A19=0,VLOOKUP(D19,'03. Insumos'!A:F,4,0),"") -> 225 | L19: =H19*J19*I19 -> 0 | M19: =L19/$L$7 -> 0 | O19: =IF(I19<>0,I19*H19*K19,) -> 0 | R19: =IF(J19<>0,J19/1.03-K19,0) -> -6.5533981
A20: =LEN(C20) -> 0 | D20: 01.01.0104 | E20: =VLOOKUP(D20,'03. Insumos'!A:D,2,0) -> Controle Tecnológico - Mobilização | F20: FAT DIRETO | G20: =VLOOKUP(D20,'03. Insumos'!A:F,3,0) -> uni | I20: 5 | J20: =IFERROR(IF(K20<>0,K20*$K$5,0),0) -> 155 | K20: =IF(A20=0,VLOOKUP(D20,'03. Insumos'!A:F,4,0),"") -> 155 | L20: =H20*J20*I20 -> 0 | M20: =L20/$L$7 -> 0 | O20: =IF(I20<>0,I20*H20*K20,) -> 0 | R20: =IF(J20<>0,J20/1.03-K20,0) -> -4.5145631
A21: =LEN(C21) -> 0 | D21: 01.01.0107 | E21: =VLOOKUP(D21,'03. Insumos'!A:D,2,0) -> Controle Tecnológico - Coleta de materiais na obra | F21: FAT DIRETO | G21: =VLOOKUP(D21,'03. Insumos'!A:F,3,0) -> uni | I21: 5 | J21: =IFERROR(IF(K21<>0,K21*$K$5,0),0) -> 155 | K21: =IF(A21=0,VLOOKUP(D21,'03. Insumos'!A:F,4,0),"") -> 155 | L21: =H21*J21*I21 -> 0 | M21: =L21/$L$7 -> 0 | O21: =IF(I21<>0,I21*H21*K21,) -> 0 | R21: =IF(J21<>0,J21/1.03-K21,0) -> -4.5145631
A22: =LEN(C22) -> 6 | C22: 01.2.2 | D22: Consultorias | K22: =IF(A22=0,VLOOKUP(D22,'03. Insumos'!A:F,4,0),"") | L22: =SUM(L23:L23) -> 0 | M22: =L22/$L$7 -> 0 | R22: =IF(J22<>0,J22/1.03-K22,0) -> 0
A23: =LEN(C23) -> 0 | D23: 01.01.0005 | E23: =VLOOKUP(D23,'03. Insumos'!A:D,2,0) -> Consultoria Estrutura | G23: =VLOOKUP(D23,'03. Insumos'!A:F,3,0) -> mês | J23: =IFERROR(IF(K23<>0,K23*$K$5,0),0) -> 3000 | K23: =IF(A23=0,VLOOKUP(D23,'03. Insumos'!A:F,4,0),"") -> 3000 | L23: =H23*J23*I23 -> 0 | M23: =L23/$L$7 -> 0 | O23: =IF(I23<>0,I23*H23*K23,) -> 0 | R23: =IF(J23<>0,J23/1.03-K23,0) -> -87.378641
A24: =LEN(C24) -> 6 | C24: 01.2.3 | D24: Seguro de Obra | K24: =IF(A24=0,VLOOKUP(D24,'03. Insumos'!A:F,4,0),"") | L24: =SUM(L25:L27) -> 0 | M24: =L24/$L$7 -> 0 | R24: =IF(J24<>0,J24/1.03-K24,0) -> 0
A25: =LEN(C25) -> 0 | D25: 01.01.0713 | E25: =VLOOKUP(D25,'03. Insumos'!A:D,2,0) -> Seguro responsabilidade civil e cruzada | F25: SERV. ESP. | G25: =VLOOKUP(D25,'03. Insumos'!A:F,3,0) -> vb | J25: =IFERROR(IF(K25<>0,K25*$K$5,0),0) -> 1 | K25: =IF(A25=0,VLOOKUP(D25,'03. Insumos'!A:F,4,0),"") -> 1 | L25: =H25*J25*I25 -> 0 | M25: =L25/$L$7 -> 0 | O25: =IF(I25<>0,I25*H25*K25,) -> 0 | R25: =IF(J25<>0,J25/1.03-K25,0) -> -0.029126214
A26: =LEN(C26) -> 0 | D26: 01.01.0714 | E26: =VLOOKUP(D26,'03. Insumos'!A:D,2,0) -> Seguro Performance Bond | G26: =VLOOKUP(D26,'03. Insumos'!A:F,3,0) -> vb | J26: =IFERROR(IF(K26<>0,K26*$K$5,0),0) -> 1 | K26: =IF(A26=0,VLOOKUP(D26,'03. Insumos'!A:F,4,0),"") -> 1 | L26: =H26*J26*I26 -> 0 | M26: =L26/$L$7 -> 0
A27: =LEN(C27) -> 0 | D27: 01.01.0773 | E27: =VLOOKUP(D27,'03. Insumos'!A:D,2,0) -> Carta fiança (10% valor) | G27: =VLOOKUP(D27,'03. Insumos'!A:F,3,0) -> vb | J27: =IFERROR(IF(K27<>0,K27*$K$5,0),0) -> 85135.685 | K27: =0.03*2837856.16 -> 85135.685 | L27: =H27*J27*I27 -> 0 | M27: =L27/$L$7 -> 0
A28: =LEN(C28) -> 3 | C28: 02. | D28: INSTALAÇÕES PROVISÓRIAS E CANTEIRO | L28: =SUMIF(A29:A53,4,L29:L53) -> 4 | M28: =L28/$L$7 -> 7.1002831e-06 | O28: =IF(I28<>0,I28*H28*K28,) -> 0 | R28: =IF(J28<>0,J28/1.03-K28,0) -> 0
A29: =LEN(C29) -> 0 | K29: =IF(A29=0,VLOOKUP(D29,'03. Insumos'!A:F,4,0),"") -> #N/A | M29: =L29/$L$7 -> 0 | O29: =IF(I29<>0,I29*H29*K29,) -> 0 | R29: =IF(J29<>0,J29/1.03-K29,0) -> 0
A30: =LEN(C30) -> 4 | C30: 02.1 | D30: Canteiro de Obras | K30: =IF(A30=0,VLOOKUP(D30,'03. Insumos'!A:F,4,0),"") | L30: =SUMIF(A31:A53,6,L31:L53) -> 4 | M30: =L30/$L$7 -> 7.1002831e-06 | O30: =IF(I30<>0,I30*H30*K30,) -> 0 | R30: =IF(J30<>0,J30/1.03-K30,0) -> 0
A31: =LEN(C31) -> 6 | C31: 02.1.1 | D31: Barraco | K31: =IF(A31=0,VLOOKUP(D31,'03. Insumos'!A:F,4,0),"") | L31: =SUM(L32:L37) -> 0 | M31: =L31/$L$7 -> 0 | O31: =IF(I31<>0,I31*H31*K31,) -> 0 | R31: =IF(J31<>0,J31/1.03-K31,0) -> 0
A32: =LEN(C32) -> 0 | D32: 01.01.0302 | E32: =VLOOKUP(D32,'03. Insumos'!A:D,2,0) -> Mudança do Barraco de Obra | F32: FAT DIRETO | G32: =VLOOKUP(D32,'03. Insumos'!A:F,3,0) -> vb | I32: 1 | J32: =IFERROR(IF(K32<>0,K32*$K$5,0),0) -> 3000 | K32: =IF(A32=0,VLOOKUP(D32,'03. Insumos'!A:F,4,0),"") -> 3000 | L32: =H32*J32*I32 -> 0 | M32: =L32/$L$7 -> 0 | O32: =IF(I32<>0,I32*H32*K32,) -> 0 | R32: =IF(J32<>0,J32/1.03-K32,0) -> -87.378641
A33: =LEN(C33) -> 0 | D33: 01.01.0716 | E33: =VLOOKUP(D33,'03. Insumos'!A:D,2,0) -> Mobiliário para barraco | F33: FAT DIRETO | G33: =VLOOKUP(D33,'03. Insumos'!A:F,3,0) -> vb | I33: 1 | J33: =IFERROR(IF(K33<>0,K33*$K$5,0),0) -> 1 | K33: =IF(A33=0,VLOOKUP(D33,'03. Insumos'!A:F,4,0),"") -> 1 | L33: =H33*J33*I33 -> 0 | M33: =L33/$L$7 -> 0
A34: =LEN(C34) -> 0 | D34: 01.01.0116 | E34: =VLOOKUP(D34,'03. Insumos'!A:D,2,0) -> Container - Refeitório | F34: FAT DIRETO | G34: =VLOOKUP(D34,'03. Insumos'!A:F,3,0) -> mês | I34: 4 | J34: =IFERROR(IF(K34<>0,K34*$K$5,0),0) -> 500 | K34: =IF(A34=0,VLOOKUP(D34,'03. Insumos'!A:F,4,0),"") -> 500 | L34: =H34*J34*I34 -> 0 | M34: =L34/$L$7 -> 0
A35: =LEN(C35) -> 0 | D35: 01.01.0110 | E35: =VLOOKUP(D35,'03. Insumos'!A:D,2,0) -> Container Almoxarifado | F35: FAT DIRETO | G35: =VLOOKUP(D35,'03. Insumos'!A:F,3,0) -> mês | I35: 4 | J35: =IFERROR(IF(K35<>0,K35*$K$5,0),0) -> 900 | K35: =IF(A35=0,VLOOKUP(D35,'03. Insumos'!A:F,4,0),"") -> 900 | L35: =H35*J35*I35 -> 0 | M35: =L35/$L$7 -> 0
A36: =LEN(C36) -> 0 | D36: 01.01.0112 | E36: =VLOOKUP(D36,'03. Insumos'!A:D,2,0) -> Container Banheiro | F36: FAT DIRETO | G36: =VLOOKUP(D36,'03. Insumos'!A:F,3,0) -> mês | I36: 4 | J36: =IFERROR(IF(K36<>0,K36*$K$5,0),0) -> 400 | K36: =IF(A36=0,VLOOKUP(D36,'03. Insumos'!A:F,4,0),"") -> 400 | L36: =H36*J36*I36 -> 0 | M36: =L36/$L$7 -> 0
A37: =LEN(C37) -> 0 | D37: 01.01.0115 | E37: =VLOOKUP(D37,'03. Insumos'!A:D,2,0) -> Container - Frete ida / volta | F37: FAT DIRETO | G37: =VLOOKUP(D37,'03. Insumos'!A:F,3,0) -> viagem | I37: =3*2 -> 6 | J37: =IFERROR(IF(K37<>0,K37*$K$5,0),0) -> 920 | K37: =IF(A37=0,VLOOKUP(D37,'03. Insumos'!A:F,4,0),"") -> 920 | L37: =H37*J37*I37 -> 0 | M37: =L37/$L$7 -> 0
A38: =LEN(C38) -> 6 | C38: 02.1.2 | D38: Tapume | K38: =IF(A38=0,VLOOKUP(D38,'03. Insumos'!A:F,4,0),"") | L38: =SUM(L39:L39) -> 0 | M38: =L38/$L$7 -> 0 | O38: =IF(I38<>0,I38*H38*K38,) -> 0 | R38: =IF(J38<>0,J38/1.03-K38,0) -> 0
A39: =LEN(C39) -> 0 | D39: 01.01.0121 | E39: =VLOOKUP(D39,'03. Insumos'!A:D,2,0) -> Tapume com telha metálica (h=2,20m) - material e mão de obra | F39: MAT CONSUMO | G39: =VLOOKUP(D39,'03. Insumos'!A:F,3,0) -> m | I39: 1 | J39: =IFERROR(IF(K39<>0,K39*$K$5,0),0) -> 530 | K39: =IF(A39=0,VLOOKUP(D39,'03. Insumos'!A:F,4,0),"") -> 530 | L39: =H39*J39*I39 -> 0 | M39: =L39/$L$7 -> 0
A40: =LEN(C40) -> 6 | C40: 02.1.3 | D40: Gabarito | K40: =IF(A40=0,VLOOKUP(D40,'03. Insumos'!A:F,4,0),"") | L40: =SUM(L41:L41) -> 0 | M40: =L40/$L$7 -> 0 | O40: =IF(I40<>0,I40*H40*K40,) -> 0 | R40: =IF(J40<>0,J40/1.03-K40,0) -> 0
A41: =LEN(C41) -> 0 | D41: 01.01.0126 | E41: =VLOOKUP(D41,'03. Insumos'!A:D,2,0) -> Gabarito - Material + Mão de Obra | F41: MAT CONSUMO | G41: =VLOOKUP(D41,'03. Insumos'!A:F,3,0) -> m | I41: =(25*2)+(34*2) -> 118 | J41: =IFERROR(IF(K41<>0,K41*$K$5,0),0) -> 120 | K41: =IF(A41=0,VLOOKUP(D41,'03. Insumos'!A:F,4,0),"") -> 120 | L41: =H41*J41*I41 -> 0 | M41: =L41/$L$7 -> 0
A42: =LEN(C42) -> 6 | C42: 02.1.1 | D42: Instalações provisórias | K42: =IF(A42=0,VLOOKUP(D42,'03. Insumos'!A:F,4,0),"") | L42: =SUM(L43:L53) -> 4 | M42: =L42/$L$7 -> 7.1002831e-06 | O42: =IF(I42<>0,I42*H42*K42,) -> 0 | R42: =IF(J42<>0,J42/1.03-K42,0) -> 0
...

Sheet 01. Resumo Final
I1: VERIFICAÇÃO GERAL
B2: RESUMO DE ORÇAMENTO PRÉ EXECUTIVO - R04 - 10/03/2025 | I2: =I20=I27=I53=#REF! -> #REF!
E4: Data de Atualização:
B5: Projeto: | C5: Ana Silva | E5: Data Base:
B6: Cidade: | C6: Rio de Janeiro | E6: 45992
B7: Bairro: | C7: Pechincha | E7: INCC (n-1):
B8: Uso: | C8: Multifamiliar | E8: 1218.747
D12: ATC: | E12: 4002.24
B13: Prazo: | C13: ='02. Orçamento'!L2 -> 36 | D13: A. PRIVATIVA: | E13: 2561.21
D14: UNIDADES | E14: 37
C16: DESCRIÇÃO | D16: TOTAL (R$) | E16: TOTAL (INCC) | F16: Perc. (%)
B18: VALOR TOTAL | D18: =D20+D27 -> 16469381 | E18: =IF($E$8=0,0,D18/$E$8) -> 13513.372 | F18: =F20+F27 -> 1
B20: CUSTO INDIRETO | D20: =SUM(D21:D26) -> 4421734.1 | E20: =IF($E$8=0,0,D20/$E$8) -> 3628.0985 | F20: =SUM(F21:F26) -> 0.2684821 | I20: =D20=#REF! -> #REF!
B21: 01 | C21: ='02. Orçamento'!D10 -> SERVIÇOS TÉCNICOS E PRELIMINARES | D21: ='02. Orçamento'!L10 -> 245350 | E21: =IF($E$8=0,0,D21/$E$8) -> 201.31332 | F21: =IF(D21<>0,D21/$D$18,) -> 0.014897341 | I21: =SUM(D21:D26)/D18 -> 0.2684821 | J21: SERVIÇOS TÉCNICOS E PRELIMINARES | K21: 516512.39 | L21: =K21=D21 -> FALSE
B22: 02 | C22: ='02. Orçamento'!D49 -> INSTALAÇÕES PROVISÓRIAS E CANTEIRO | D22: ='02. Orçamento'!L49 -> 288861.24 | E22: =IF($E$8=0,0,D22/$E$8) -> 237.01493 | F22: =IF(D22<>0,D22/$D$18,) -> 0.017539289 | J22: INSTALAÇÕES PROVISÓRIAS E CANTEIRO | K22: 366211.25 | L22: =K22=D22 -> FALSE
B23: 03 | C23: ='02. Orçamento'!D72 -> SEGURANÇA DO TRABALHO E PROTEÇÕES | D23: ='02. Orçamento'!L72 -> 215613.63 | E23: =IF($E$8=0,0,D23/$E$8) -> 176.91418 | F23: =IF(D23<>0,D23/$D$18,) -> 0.013091787 | J23: SEGURANÇA DO TRABALHO E PROTEÇÕES | K23: 238669.84 | L23: =K23=D23 -> FALSE
B24: 04 | C24: ='02. Orçamento'!D124 -> MÁQUINAS E EQUIPAMENTOS | D24: ='02. Orçamento'!L124 -> 426714.53 | E24: =IF($E$8=0,0,D24/$E$8) -> 350.1256 | F24: =IF(D24<>0,D24/$D$18,) -> 0.025909566 | J24: MÁQUINAS E EQUIPAMENTOS | K24: 282257.69 | L24: =K24=D24 -> FALSE
B25: 05 | C25: ='02. Orçamento'!D205 -> MÃO DE OBRA DE APOIO / ENGENHARIA | D25: ='02. Orçamento'!L205 -> 2895074.7 | E25: =IF($E$8=0,0,D25/$E$8) -> 2375.4518 | F25: =IF(D25<>0,D25/$D$18,) -> 0.17578527 | J25: MÃO DE OBRA DE APOIO / ENGENHARIA | K25: 1105068.2 | L25: =K25=D25 -> FALSE
B26: 06 | C26: ='02. Orçamento'!D270 -> DESPESAS OPERACIONAIS | D26: ='02. Orçamento'!L270 -> 350120 | E26: =IF($E$8=0,0,D26/$E$8) -> 287.27866 | F26: =IF(D26<>0,D26/$D$18,) -> 0.021258843 | J26: DESPESAS OPERACIONAIS | K26: 419700 | L26: =K26=D26 -> FALSE
B27: CUSTO DIRETO | D27: =SUM(D28:D49) -> 12047647 | E27: =IF($E$8=0,0,D27/$E$8) -> 9885.2735 | F27: =SUM(F28:F49) -> 0.7315179 | I27: =D27=#REF! -> #REF! | L27: =K27=D27 -> FALSE
B28: 07 | C28: ='02. Orçamento'!D298 -> MOVIMENTAÇÃO DE TERRA / DEMOLIÇÃO | D28: ='02. Orçamento'!L298 -> 255846.5 | E28: =IF($E$8=0,0,D28/$E$8) -> 209.92585 | F28: =IF(D28<>0,D28/$D$18,) -> 0.015534676 | J28: DEMOLIÇÃO E ACERTOS | K28: 106481.39 | L28: =K28=D28 -> FALSE
B29: 08 | C29: ='02. Orçamento'!D328 -> INFRAESTRUTURA | D29: ='02. Orçamento'!L328 -> 970337.51 | E29: =IF($E$8=0,0,D29/$E$8) -> 796.17633 | F29: =IF(D29<>0,D29/$D$18,) -> 0.058917665 | J29: INFRAESTRUTURA | K29: 526061.97 | L29: =K29=D29 -> FALSE
B30: 09 | C30: ='02. Orçamento'!D516 -> SUPRAESTRUTURA | D30: ='02. Orçamento'!L516 -> 2724364.1 | E30: =IF($E$8=0,0,D30/$E$8) -> 2235.3812 | F30: =IF(D30<>0,D30/$D$18,) -> 0.16541994 | J30: SUPRAESTRUTURA | K30: 2956692.1 | L30: =K30=D30 -> FALSE
B31: 10 | C31: ='02. Orçamento'!D571 -> PAREDES E PAINÉIS | D31: ='02. Orçamento'!L571 -> 651943.64 | E31: =IF($E$8=0,0,D31/$E$8) -> 534.92943 | F31: =IF(D31<>0,D31/$D$18,) -> 0.039585192 | J31: PAREDES E PAINÉIS | K31: 829933.93 | L31: =K31=D31 -> FALSE
B32: 11 | C32: ='02. Orçamento'!D700 -> INSTALAÇÕES | D32: ='02. Orçamento'!L700 -> 2424709 | E32: =IF($E$8=0,0,D32/$E$8) -> 1989.5097 | F32: =IF(D32<>0,D32/$D$18,) -> 0.14722526 | J32: INSTALAÇÕES | K32: 3332378.2 | L32: =K32=D32 -> FALSE
B33: 12 | C33: ='02. Orçamento'!D736 -> IMPERMEABILIZAÇÃO | D33: ='02. Orçamento'!L736 -> 241413.07 | E33: =IF($E$8=0,0,D33/$E$8) -> 198.08301 | F33: =IF(D33<>0,D33/$D$18,) -> 0.014658296 | J33: IMPERMEABILIZAÇÃO | K33: 374231.47 | L33: =K33=D33 -> FALSE
B34: 13 | C34: ='02. Orçamento'!D771 -> MASSA | D34: ='02. Orçamento'!L771 -> 904246.01 | E34: =IF($E$8=0,0,D34/$E$8) -> 741.94727 | F34: =IF(D34<>0,D34/$D$18,) -> 0.054904673 | J34: MASSA | K34: 1132893.3 | L34: =K34=D34 -> FALSE
B35: 14 | C35: ='02. Orçamento'!D802 -> FORRO | D35: ='02. Orçamento'!L802 -> 34872.39 | E35: =IF($E$8=0,0,D35/$E$8) -> 28.613314 | F35: =IF(D35<>0,D35/$D$18,) -> 0.0021174074 | J35: FORRO | K35: 200048.28 | L35: =K35=D35 -> FALSE
B36: 15 | C36: ='02. Orçamento'!D810 -> REVESTIMENTOS INTERNOS | D36: ='02. Orçamento'!L810 -> 829026.71 | E36: =IF($E$8=0,0,D36/$E$8) -> 680.22872 | F36: =IF(D36<>0,D36/$D$18,) -> 0.050337453 | J36: REVESTIMENTOS INTERNOS E EXTERNOS | K36: 1298586.2 | L36: =K36=D36 -> FALSE
B37: 16 | C37: ='02. Orçamento'!D921 -> PEDRAS NATURAIS E SINTÉTICAS | D37: ='02. Orçamento'!L921 -> 203956.92 | E37: =IF($E$8=0,0,D37/$E$8) -> 167.34968 | F37: =IF(D37<>0,D37/$D$18,) -> 0.012384006 | J37: PEDRAS NATURAIS E SINTÉTICAS | K37: 315285.35 | L37: =K37=D37 -> FALSE
B38: 17 | C38: ='02. Orçamento'!D987 -> ESQUADRIAS EM ALUMÍNIO, FERRO E MADEIRA | D38: ='02. Orçamento'!L987 -> 875132.39 | E38: =IF($E$8=0,0,D38/$E$8) -> 718.05911 | F38: =IF(D38<>0,D38/$D$18,) -> 0.053136931 | J38: ESQUADRIAS EM ALUMÍNIO E MADEIRA | K38: 2043561.7 | L38: =K38=D38 -> FALSE
B39: 18 | C39: ='02. Orçamento'!D1079 -> FACHADA | D39: ='02. Orçamento'!L1079 -> 580194.62 | E39: =IF($E$8=0,0,D39/$E$8) -> 476.05829 | F39: =IF(D39<>0,D39/$D$18,) -> 0.035228683 | J39: FACHADA | K39: 563518.38 | L39: =K39=D39 -> FALSE
B40: 19 | C40: ='02. Orçamento'!D1124 -> ELEVADORES | D40: ='02. Orçamento'!L1124 -> 178000 | E40: =IF($E$8=0,0,D40/$E$8) -> 146.05164 | F40: =IF(D40<>0,D40/$D$18,) -> 0.010807935 | J40: ELEVADORES | K40: 290000 | L40: =K40=D40 -> FALSE
B41: 20 | C41: ='02. Orçamento'!D1130 -> PINTURA | D41: ='02. Orçamento'!L1130 -> 417699.28 | E41: =IF($E$8=0,0,D41/$E$8) -> 342.72846 | F41: =IF(D41<>0,D41/$D$18,) -> 0.025362172 | J41: PINTURA | K41: 446866.2 | L41: =K41=D41 -> FALSE
B42: 21 | C42: ='02. Orçamento'!D1164 -> LOUÇAS E METAIS | D42: ='02. Orçamento'!L1164 -> 161044.31 | E42: =IF($E$8=0,0,D42/$E$8) -> 132.13924 | F42: =IF(D42<>0,D42/$D$18,) -> 0.0097784066 | J42: LOUÇAS E METAIS | K42: 145944.21 | L42: =K42=D42 -> FALSE
B43: 22 | C43: ='02. Orçamento'!D1196 -> AR CONDICIONADO E EXAUSTÃO | D43: ='02. Orçamento'!L1196 -> 357846.29 | E43: =IF($E$8=0,0,D43/$E$8) -> 293.61819 | F43: =IF(D43<>0,D43/$D$18,) -> 0.021727974 | J43: ITENS DIVEROS | K43: 0 | L43: =K43=D43 -> FALSE
B44: 23 | C44: ='02. Orçamento'!D1205 -> EQUIPAMENTOS ESPECIAIS | D44: ='02. Orçamento'!L1205 -> 64065.424 | E44: =IF($E$8=0,0,D44/$E$8) -> 52.566631 | F44: =IF(D44<>0,D44/$D$18,) -> 0.0038899715 | J44: ITENS DIVEROS | K44: 0 | L44: =K44=D44 -> FALSE
B45: 24 | C45: ='02. Orçamento'!D1234 -> LIMPEZA DE OBRA | D45: ='02. Orçamento'!L1234 -> 57871.36 | E45: =IF($E$8=0,0,D45/$E$8) -> 47.48431 | F45: =IF(D45<>0,D45/$D$18,) -> 0.0035138757 | J45: LIMPEZA DE OBRA | K45: 86087.383 | L45: =K45=D45 -> FALSE
B46: 25 | C46: ='02. Orçamento'!D1245 -> ÁREA COMUM | D46: ='02. Orçamento'!L1245 -> 115077.84 | E46: =IF($E$8=0,0,D46/$E$8) -> 94.423073 | F46: =IF(D46<>0,D46/$D$18,) -> 0.0069873806 | J46: EVENTUAIS | K46: 527309.68 | L46: =K46=D46 -> FALSE
B47: 25 | C47: =#REF! -> #REF! | D47: =IFERROR(#REF!,0) -> 0 | F47: =IF(D47<>0,D47/$D$18,) -> 0
...

Sheet 02. Dados Gerais
A1: DADOS GERAIS
A4: =CONCATENATE('01. Resumo Final'!B5," ",'01. Resumo Final'!C5) -> Projeto: Ana Silva
A5: =CONCATENATE('01. Resumo Final'!B6," ",'01. Resumo Final'!C6) -> Cidade: Rio de Janeiro
A6: =CONCATENATE('01. Resumo Final'!B7," ",'01. Resumo Final'!C7) -> Bairro: Pechincha
I8: uso
A9: USO: | B9: Residencial | F9: PADRÃO : | G9: Residencial | I9: Comercial
I10: Residencial
I11: Misto
A12: ÍNICIO DO ORÇAMENTO: | B12: 45950 | F12: QUANT. DE BLOCOS: | G12: 1
A14: MÊS BASE: | B14: 45962 | F14: QUANT. DE APARTAMENTOS: | G14: 105
A16: INCC (MÊS BASE-2): | B16: 1218.747 | F16: QUANT. DE QUARTOS:
A18: ÁREA DE CONSTRUÇÃO: | B18: ='01. Resumo Final'!E12 -> 4002.24 | F18: QUANT. DE SALAS COMERCIAIS:
A20: ÁREA PRIVATIVA | B20: 3512.2 | F20: QUANT. DE SALAS CORPORATIVAS:
A22: ÁREA EQUIVALENTE: | B22: =B18*1.2 -> 4802.688 | F22: QUANT. DE LOJAS
A24: PRAZO (MESES): | B24: 16 | F24: TOTAL DE UNIDADES: | G24: =G22+G20+G18+G14 -> 105
A26: TIPOLOGIA
A28: DESCRIÇÃO: | B28: Prédio residencial com 1 bloco, térreo e 7 pavimentos tipos e cobertura rooftop
A30: TIPOLOGIA:
A32: Subsolo | B32: não | F32: Pavimento Tipo 1 | G32: sim
A33: Térreo | B33: sim | F33: Pavimento Tipo 2 | G33: não
A34: Embasamento | B34: não | F34: Cobertura | G34: sim
A35: Jirau no térreo | B35: não | F35: Casa de Máquinas | G35: não
A36: Pavimento garagem elevada | B36: não | F36: Telhado | G36: sim
A38: TIPO DE FUNDAÇÃO: | B38: Estaca Hélice Contínua | F38: TIPO DE ESTRUTURA: | G38: Pilotis + Alvenaria Estrutural
A40: LATERAIS COM VIZINHO: | B40: Não | F40: TIPO DE FACHADA: | G40: Pintura Acrílica Externa

Sheet 03. Quadro de Áreas
E2: Data: | H2: 41648
E3: Código: | H3: 002.14 - Monumental Niemeyer
E4: Revisão: | H4: 00
B5: Quadro de Áreas
B7: ÁREA TOTAL DO TERRENO | E7: 3847.6
A9: FILTRO | B9: Pavimento | C9: Área Existente | D9: Qtde | E9: TOTAL | F9: Índice | G9: Área Equivalente | H9: Área Privativa | I9: Área Privativa Total
A11: =IF(E11>0,1,"X") -> 1 | B11: BLOCO 1 | E11: =SUM(E12:E61) -> 33721.51 | G11: =SUM(G12:G61) -> 31467.523 | I11: =SUM(I12:I61) -> 11533.8
A12: =IF(E12>0,1,"X") -> 1 | B12: 1º SUBSOLO ENTERRADO COM ÁGUA | C12: 3811.09 | D12: 1 | E12: =C12*D12 -> 3811.09 | F12: 1 | G12: =E12*F12 -> 3811.09 | I12: =+H12*D12 -> 0
A13: =IF(E13>0,1,"X") -> 1 | B13: 2º SUBSOLO ENTERRADO COM ÁGUA | C13: 3712.11 | D13: 1 | E13: =C13*D13 -> 3712.11 | F13: 1 | G13: =E13*F13 -> 3712.11 | I13: =+H13*D13 -> 0
A14: =IF(E14>0,1,"X") -> 1 | B14: 3º SUBSOLO ENTERRADO COM ÁGUA | C14: 3742.8 | D14: 1 | E14: =C14*D14 -> 3742.8 | F14: 1 | G14: =E14*F14 -> 3742.8 | I14: =+H14*D14 -> 0
A15: =IF(E15>0,1,"X") -> 1 | B15: RESERVATÓRIO ENTERRADO COM ÁGUA | C15: =181.49+52.5+52.5 -> 286.49 | D15: 1 | E15: =C15*D15 -> 286.49 | F15: 1 | G15: =E15*F15 -> 286.49 | H15: 0 | I15: =+H15*D15 -> 0
A16: =IF(E16>0,1,"X") -> X | B16: RESERVATÓRIO SEMI-ENTERRADO COM ÁGUA | E16: =C16*D16 -> 0 | F16: 0.9 | G16: =E16*F16 -> 0 | I16: =+H16*D16 -> 0
A17: =IF(E17>0,1,"X") -> X | B17: SEMI-ENTERRADO COM ÁGUA | E17: =C17*D17 -> 0 | F17: 0.9 | G17: =E17*F17 -> 0 | I17: =+H17*D17 -> 0
A18: =IF(E18>0,1,"X") -> X | B18: SEMI-ENTERRADO SEM ÁGUA | E18: =C18*D18 -> 0 | F18: 0.7 | G18: =E18*F18 -> 0 | I18: =+H18*D18 -> 0
A19: =IF(E19>0,1,"X") -> 1 | B19: LOJAS (TÉRREO) | C19: =336.89 -> 336.89 | D19: 1 | E19: =C19*D19 -> 336.89 | F19: 0.75 | G19: =E19*F19 -> 252.6675 | H19: =C19 -> 336.89 | I19: =+H19*D19 -> 336.89
A20: =IF(E20>0,1,"X") -> 1 | B20: LOJAS (2º PAVIMENTO) | C20: =509.6 -> 509.6 | D20: 1 | E20: =C20*D20 -> 509.6 | F20: 0.75 | G20: =E20*F20 -> 382.2 | H20: =C20 -> 509.6 | I20: =+H20*D20 -> 509.6
A21: =IF(E21>0,1,"X") -> 1 | B21: TÉRREO COBERTO FECHADO | C21: 144.29 | D21: 1 | E21: =C21*D21 -> 144.29 | F21: 1 | G21: =E21*F21 -> 144.29 | H21: 0 | I21: =+H21*D21 -> 0
A22: =IF(E22>0,1,"X") -> 1 | B22: TÉRREO COBERTO ABERTO | C22: 1420.48 | D22: 1 | E22: =C22*D22 -> 1420.48 | F22: 0.75 | G22: =E22*F22 -> 1065.36 | I22: =+H22*D22 -> 0
A23: =IF(E23>0,1,"X") -> X | B23: TÉRREO COBERTO FECHADO (GARAGEM) | E23: =C23*D23 -> 0 | F23: 0.6 | G23: =E23*F23 -> 0 | H23: 0 | I23: =+H23*D23 -> 0
A24: =IF(E24>0,1,"X") -> 1 | B24: TÉRREO DESCOBERTO SOBRE LAJE COM OU SEM GARAGEM | C24: 1258.9 | D24: 1 | E24: =C24*D24 -> 1258.9 | F24: 0.5 | G24: =E24*F24 -> 629.45 | I24: =+H24*D24 -> 0
A25: =IF(E25>0,1,"X") -> X | B25: TÉRREO DESCOBERTO SOBRE SOLO | E25: =C25*D25 -> 0 | F25: 0.25 | G25: =E25*F25 -> 0 | I25: =+H25*D25 -> 0
A26: =IF(E26>0,1,"X") -> X | B26: VIAS INTERNAS | E26: =C26*D26 -> 0 | F26: 0.3 | G26: =E26*F26 -> 0 | I26: =+H26*D26 -> 0
A27: =IF(E27>0,1,"X") -> X | B27: VIAS INTERNAS (CALÇADAS) | E27: =C27*D27 -> 0 | F27: 0.25 | G27: =E27*F27 -> 0 | I27: =+H27*D27 -> 0
A28: =IF(E28>0,1,"X") -> X | B28: LAZER COBERTO | E28: =C28*D28 -> 0 | F28: 1 | G28: =E28*F28 -> 0 | I28: =+H28*D28 -> 0
A29: =IF(E29>0,1,"X") -> X | B29: LAZER DESCOBERTO | E29: =C29*D29 -> 0 | F29: 0.5 | G29: =E29*F29 -> 0 | I29: =+H29*D29 -> 0
A30: =IF(E30>0,1,"X") -> X | B30: CONEXÃO BLOCOS FECHADO | E30: =C30*D30 -> 0 | F30: 1 | G30: =E30*F30 -> 0 | I30: =+H30*D30 -> 0
A31: =IF(E31>0,1,"X") -> 1 | B31: CONEXÃO BLOCOS (TERRAÇO 3º PAVIMENTO) | C31: 531.71 | D31: 1 | E31: =C31*D31 -> 531.71 | F31: 0.5 | G31: =E31*F31 -> 265.855 | I31: =+H31*D31 -> 0
A32: =IF(E32>0,1,"X") -> 1 | B32: CONEXÃO BLOCOS (TERRAÇO 12º PAVIMENTO) | C32: 536.34 | D32: 1 | E32: =C32*D32 -> 536.34 | F32: 0.5 | G32: =E32*F32 -> 268.17 | I32: =+H32*D32 -> 0
A33: =IF(E33>0,1,"X") -> X | B33: PISCINA | E33: =C33*D33 -> 0 | F33: 1 | G33: =E33*F33 -> 0 | H33: 0 | I33: =+H33*D33 -> 0
A34: =IF(E34>0,1,"X") -> X | B34: JIRAU VAZIO (VAZIO 1° PAV.) | E34: =C34*D34 -> 0 | F34: 0.35 | G34: =E34*F34 -> 0 | H34: 0 | I34: =+H34*D34 -> 0
A35: =IF(E35>0,1,"X") -> X | B35: JIRAU COMO DEPENDÊNCIA | E35: =C35*D35 -> 0 | F35: 0.75 | G35: =E35*F35 -> 0 | I35: =+H35*D35 -> 0
A36: =IF(E36>0,1,"X") -> X | B36: JIRAU FECHADO COMO GARAGEM | E36: =C36*D36 -> 0 | F36: 0.6 | G36: =E36*F36 -> 0 | I36: =+H36*D36 -> 0
A37: =IF(E37>0,1,"X") -> X | B37: JIRAU ABERTO COMO GARAGEM | E37: =C37*D37 -> 0 | F37: 0.5 | G37: =E37*F37 -> 0 | I37: =+H37*D37 -> 0
A38: =IF(E38>0,1,"X") -> X | B38: JIRAU COBERTO FECHADO | E38: =C38*D38 -> 0 | F38: 1 | G38: =E38*F38 -> 0 | I38: =+H38*D38 -> 0
A39: =IF(E39>0,1,"X") -> X | B39: GARAGEM ELEVADA FECHADA COBERTA | E39: =C39*D39 -> 0 | F39: 0.6 | G39: =E39*F39 -> 0 | I39: =+H39*D39 -> 0
A40: =IF(E40>0,1,"X") -> X | B40: GARAGEM ELEVADA ABERTA COBERTA | E40: =C40*D40 -> 0 | F40: 0.5 | G40: =E40*F40 -> 0 | H40: 0 | I40: =+H40*D40 -> 0
A41: =IF(E41>0,1,"X") -> X | B41: GARAGEM ELEVADA DESCOBERTA | E41: =C41*D41 -> 0 | F41: 0.5 | G41: =E41*F41 -> 0 | H41: 0 | I41: =+H41*D41 -> 0
A42: =IF(E42>0,1,"X") -> X | B42: PUC GARAGEM SOBRE SOLO | E42: =C42*D42 -> 0 | F42: 0.25 | G42: =E42*F42 -> 0 | I42: =+H42*D42 -> 0
A43: =IF(E43>0,1,"X") -> X | B43: PUC GARAGEM ELEVADA DESCOBERTA | E43: =C43*D43 -> 0 | F43: 0.5 | G43: =E43*F43 -> 0 | I43: =+H43*D43 -> 0
A44: =IF(E44>0,1,"X") -> X | B44: GARAGEM SOB TRANSIÇÃO | E44: =C44*D44 -> 0 | F44: 0.7 | G44: =E44*F44 -> 0 | I44: =+H44*D44 -> 0
...

Sheet 02. Orçamento
E1: PLANILHA ORÇAMENTÁRIA DETALHADA | K1: formulado | L1: PRAZO (meses)
L2: 36
I3: =L2 -> 36
K4: % DISTR
F5: CATEGORIA | G5: UNIDADE | H5: QTD. | I5: QTD. TOTAL | J5: VALOR | K5: 1 | L5: TOTAL | O5: VALOR SEM % DISTR
B7: CUSTO TOTAL | L7: =SUM(L9+L297) -> 16469381 | M7: =L7/$L$7 -> 1 | N7: =P7=L7 -> #VALUE! | O7: =SUM(O10:O1246) -> #VALUE! | P7: =O7*K5 -> #VALUE!
B8: 0 | C8: 0 | D8: 0 | E8: 0 | G8: 0 | H8: 0 | J8: =IFERROR(IF(K8<>0,K8*$K$5,0),0) -> 0 | M8: =L8/$L$7 -> 0
A9: =LEN(C9) -> 1 | C9: I | D9: DESPESAS INDIRETAS | L9: =SUMIF(A10:A296,3,L10:L296) -> 4421734.1 | M9: =L9/$L$7 -> 0.2684821 | O9: =IF(I9<>0,I9*H9*K9,) -> 0 | R9: =IF(J9<>0,J9/1.03-K9,0) -> 0
A10: =LEN(C10) -> 3 | C10: 01. | D10: SERVIÇOS TÉCNICOS E PRELIMINARES | L10: =SUMIF(A11:A48,4,L11:L48) -> 245350 | M10: =L10/$L$7 -> 0.014897341 | O10: =IF(I10<>0,I10*H10*K10,) -> 0 | R10: =IF(J10<>0,J10/1.03-K10,0) -> 0
A11: =LEN(C11) -> 4 | C11: 01.1 | D11: Serviços Preliminares | K11: =IF(A11=0,VLOOKUP(D11,'03. Insumos'!A:F,4,0),"") | L11: =SUMIF(A12:A18,6,L12:L18) -> 18050 | M11: =L11/$L$7 -> 0.0010959732 | O11: =IF(I11<>0,I11*H11*K11,) -> 0 | R11: =IF(J11<>0,J11/1.03-K11,0) -> 0
A12: =LEN(C12) -> 6 | C12: 01.1.1 | D12: Serviços Preliminares | H12: 1 | K12: =IF(A12=0,VLOOKUP(D12,'03. Insumos'!A:F,4,0),"") | L12: =SUM(L13:L18) -> 18050 | M12: =L12/$L$7 -> 0.0010959732 | O12: =IF(I12<>0,I12*H12*K12,) -> 0 | R12: =IF(J12<>0,J12/1.03-K12,0) -> 0
A13: 0 | D13: 01.01.0713 | E13: =VLOOKUP(D13,'03. Insumos'!A:D,2,0) -> Seguro responsabilidade civil e cruzada | F13: RASA | G13: =VLOOKUP(D13,'03. Insumos'!A:F,3,0) -> vb | I13: 1 | J13: =IFERROR(IF(K13<>0,K13*$K$5,0),0) -> 1 | K13: =IF(A13=0,VLOOKUP(D13,'03. Insumos'!A:F,4,0),"") -> 1 | L13: =H13*J13*I13 -> 0 | M13: =L13/$L$7 -> 0
A14: 0 | D14: 01.01.0001 | E14: =VLOOKUP(D14,'03. Insumos'!A:D,2,0) -> Placa de Obra | F14: RASA | G14: =VLOOKUP(D14,'03. Insumos'!A:F,3,0) -> vb | H14: 8700 | I14: 1 | J14: 1 | K14: =IF(A14=0,VLOOKUP(D14,'03. Insumos'!A:F,4,0),"") -> 1 | L14: =H14*J14*I14 -> 8700 | M14: =L14/$L$7 -> 0.00052825299
A15: =LEN(C15) -> 0 | D15: 01.01.3143 | E15: =VLOOKUP(D15,'03. Insumos'!A:D,2,0) -> Licença CET-RIO | F15: RASA | G15: =VLOOKUP(D15,'03. Insumos'!A:F,3,0) -> vb | I15: 1 | J15: 1 | K15: =IF(A15=0,VLOOKUP(D15,'03. Insumos'!A:F,4,0),"") -> 1 | L15: =H15*J15*I15 -> 0 | M15: =L15/$L$7 -> 0 | O15: =IF(I15<>0,I15*H15*K15,) -> 0 | R15: =IF(J15<>0,J15/1.03-K15,0) -> -0.029126214
A16: =LEN(C16) -> 0 | D16: 01.01.3175 | E16: =VLOOKUP(D16,'03. Insumos'!A:D,2,0) -> Licença Água e Esgoto | F16: RASA | G16: =VLOOKUP(D16,'03. Insumos'!A:F,3,0) -> vb | H16: 9000 | I16: 1 | J16: 1 | K16: =IF(A16=0,VLOOKUP(D16,'03. Insumos'!A:F,4,0),"") -> 1 | L16: =H16*J16*I16 -> 9000 | M16: =L16/$L$7 -> 0.00054646861 | O16: =IF(I16<>0,I16*H16*K16,) -> 9000 | R16: =IF(J16<>0,J16/1.03-K16,0) -> -0.029126214
A17: =LEN(C17) -> 0 | D17: 01.01.3174 | E17: =VLOOKUP(D17,'03. Insumos'!A:D,2,0) -> Licença Tapume | F17: RASA | G17: =VLOOKUP(D17,'03. Insumos'!A:F,3,0) -> vb | I17: 1 | J17: 1 | K17: =IF(A17=0,VLOOKUP(D17,'03. Insumos'!A:F,4,0),"") -> 1 | L17: =H17*J17*I17 -> 0 | M17: =L17/$L$7 -> 0 | O17: =IF(I17<>0,I17*H17*K17,) -> 0 | R17: =IF(J17<>0,J17/1.03-K17,0) -> -0.029126214
A18: =LEN(C18) -> 0 | D18: 01.01.1305 | E18: =VLOOKUP(D18,'03. Insumos'!A:D,2,0) -> ART | F18: RASA | G18: =VLOOKUP(D18,'03. Insumos'!A:F,3,0) -> vb | H18: 350 | I18: 1 | J18: 1 | K18: =IF(A18=0,VLOOKUP(D18,'03. Insumos'!A:F,4,0),"") -> 1 | L18: =H18*J18*I18 -> 350 | M18: =L18/$L$7 -> 2.1251557e-05 | O18: =IF(I18<>0,I18*H18*K18,) -> 350 | R18: =IF(J18<>0,J18/1.03-K18,0) -> -0.029126214
A19: =LEN(C19) -> 4 | C19: 01.2 | D19: Serviços Técnicos | K19: =IF(A19=0,VLOOKUP(D19,'03. Insumos'!A:F,4,0),"") | L19: =SUMIF(A20:A46,6,L20:L48) -> 227300 | M19: =L19/$L$7 -> 0.013801368 | O19: =IF(I19<>0,I19*H19*K19,) -> 0 | R19: =IF(J19<>0,J19/1.03-K19,0) -> 0
A20: =LEN(C20) -> 6 | C20: 01.2.2 | D20: Projetos - Custo Incorporação | K20: =IF(A20=0,VLOOKUP(D20,'03. Insumos'!A:F,4,0),"") | L20: =SUM(L21:L26) -> 0 | M20: =L20/$L$7 -> 0 | R20: =IF(J20<>0,J20/1.03-K20,0) -> 0
A21: =LEN(C21) -> 0 | D21: 01.01.2595 | E21: =VLOOKUP(D21,'03. Insumos'!A:D,2,0) -> Projeto de Instalações e Combate a Incêndio | F21: FAT DIRETO | G21: =VLOOKUP(D21,'03. Insumos'!A:F,3,0) -> vb | I21: 1 | J21: =IFERROR(IF(K21<>0,K21*$K$5,0),0) -> 1 | K21: =IF(A21=0,VLOOKUP(D21,'03. Insumos'!A:F,4,0),"") -> 1 | L21: =H21*J21*I21 -> 0 | M21: =L21/$L$7 -> 0 | O21: =IF(I21<>0,I21*H21*K21,) -> 0 | R21: =IF(J21<>0,J21/1.03-K21,0) -> -0.029126214
A22: =LEN(C22) -> 0 | D22: 01.01.2596 | E22: =VLOOKUP(D22,'03. Insumos'!A:D,2,0) -> Projeto de Exaustão Mecânica e Ar Condicionado | F22: FAT DIRETO | G22: =VLOOKUP(D22,'03. Insumos'!A:F,3,0) -> vb | I22: 1 | J22: =IFERROR(IF(K22<>0,K22*$K$5,0),0) -> 1 | K22: =IF(A22=0,VLOOKUP(D22,'03. Insumos'!A:F,4,0),"") -> 1 | L22: =H22*J22*I22 -> 0 | M22: =L22/$L$7 -> 0 | O22: =IF(I22<>0,I22*H22*K22,) -> 0 | R22: =IF(J22<>0,J22/1.03-K22,0) -> -0.029126214
A23: =LEN(C23) -> 0 | D23: 01.01.2597 | E23: =VLOOKUP(D23,'03. Insumos'!A:D,2,0) -> Projeto de Estrutura | F23: FAT DIRETO | G23: =VLOOKUP(D23,'03. Insumos'!A:F,3,0) -> vb | I23: 1 | J23: =IFERROR(IF(K23<>0,K23*$K$5,0),0) -> 1 | K23: =IF(A23=0,VLOOKUP(D23,'03. Insumos'!A:F,4,0),"") -> 1 | L23: =H23*J23*I23 -> 0 | M23: =L23/$L$7 -> 0 | O23: =IF(I23<>0,I23*H23*K23,) -> 0 | R23: =IF(J23<>0,J23/1.03-K23,0) -> -0.029126214
A24: =LEN(C24) -> 0 | D24: 01.01.2598 | E24: =VLOOKUP(D24,'03. Insumos'!A:D,2,0) -> Projeto de Fundações | F24: FAT DIRETO | G24: =VLOOKUP(D24,'03. Insumos'!A:F,3,0) -> vb | I24: 1 | J24: =IFERROR(IF(K24<>0,K24*$K$5,0),0) -> 1 | K24: =IF(A24=0,VLOOKUP(D24,'03. Insumos'!A:F,4,0),"") -> 1 | L24: =H24*J24*I24 -> 0 | M24: =L24/$L$7 -> 0 | O24: =IF(I24<>0,I24*H24*K24,) -> 0 | R24: =IF(J24<>0,J24/1.03-K24,0) -> -0.029126214
A25: =LEN(C25) -> 0 | D25: 01.01.2599 | E25: =VLOOKUP(D25,'03. Insumos'!A:D,2,0) -> Projeto Executivo de Arquitetura | F25: FAT DIRETO | G25: =VLOOKUP(D25,'03. Insumos'!A:F,3,0) -> vb | I25: 1 | J25: =IFERROR(IF(K25<>0,K25*$K$5,0),0) -> 1 | K25: =IF(A25=0,VLOOKUP(D25,'03. Insumos'!A:F,4,0),"") -> 1 | L25: =H25*J25*I25 -> 0 | M25: =L25/$L$7 -> 0 | O25: =IF(I25<>0,I25*H25*K25,) -> 0 | R25: =IF(J25<>0,J25/1.03-K25,0) -> -0.029126214
A26: =LEN(C26) -> 0 | D26: 01.01.2600 | E26: =VLOOKUP(D26,'03. Insumos'!A:D,2,0) -> Projeto de Instalações | F26: FAT DIRETO | G26: =VLOOKUP(D26,'03. Insumos'!A:F,3,0) -> vb | I26: 1 | J26: =IFERROR(IF(K26<>0,K26*$K$5,0),0) -> 1 | K26: =IF(A26=0,VLOOKUP(D26,'03. Insumos'!A:F,4,0),"") -> 1 | L26: =H26*J26*I26 -> 0 | M26: =L26/$L$7 -> 0 | O26: =IF(I26<>0,I26*H26*K26,) -> 0 | R26: =IF(J26<>0,J26/1.03-K26,0) -> -0.029126214
A27: =LEN(C27) -> 6 | C27: 01.2.3 | D27: Consultorias | K27: =IF(A27=0,VLOOKUP(D27,'03. Insumos'!A:F,4,0),"") | L27: =SUM(L28:L35) -> 182400 | M27: =L27/$L$7 -> 0.011075097 | R27: =IF(J27<>0,J27/1.03-K27,0) -> 0
A28: =LEN(C28) -> 0 | D28: 01.01.2456 | E28: =VLOOKUP(D28,'03. Insumos'!A:D,2,0) -> Consultoria de Fundação | F28: FAT DIRETO | G28: =VLOOKUP(D28,'03. Insumos'!A:F,3,0) -> vb | H28: 8000 | I28: 3 | J28: =IFERROR(IF(K28<>0,K28*$K$5,0),0) -> 1 | K28: =IF(A28=0,VLOOKUP(D28,'03. Insumos'!A:F,4,0),"") -> 1 | L28: =H28*J28*I28 -> 24000 | M28: =L28/$L$7 -> 0.0014572496 | O28: =IF(I28<>0,I28*H28*K28,) -> 24000 | R28: =IF(J28<>0,J28/1.03-K28,0) -> -0.029126214
A29: =LEN(C29) -> 0 | D29: 01.01.2602 | E29: =VLOOKUP(D29,'03. Insumos'!A:D,2,0) -> Consultoria de Estrutura | F29: FAT DIRETO | G29: =VLOOKUP(D29,'03. Insumos'!A:F,3,0) -> vb | H29: 9000 | J29: 1 | K29: =IF(A29=0,VLOOKUP(D29,'03. Insumos'!A:F,4,0),"") -> 1 | L29: =H29*J29*I29 -> 0 | M29: =L29/$L$7 -> 0 | O29: =IF(I29<>0,I29*H29*K29,) -> 0 | R29: =IF(J29<>0,J29/1.03-K29,0) -> -0.029126214
A30: =LEN(C30) -> 0 | D30: 01.01.2603 | E30: =VLOOKUP(D30,'03. Insumos'!A:D,2,0) -> Consultoria de Fachada | F30: FAT DIRETO | G30: =VLOOKUP(D30,'03. Insumos'!A:F,3,0) -> vb | H30: 4000 | J30: =IFERROR(IF(K30<>0,K30*$K$5,0),0) -> 1 | K30: =IF(A30=0,VLOOKUP(D30,'03. Insumos'!A:F,4,0),"") -> 1 | L30: =H30*J30*I30 -> 0 | M30: =L30/$L$7 -> 0 | O30: =IF(I30<>0,I30*H30*K30,) -> 0 | R30: =IF(J30<>0,J30/1.03-K30,0) -> -0.029126214
A31: =LEN(C31) -> 0 | D31: 01.01.2604 | E31: =VLOOKUP(D31,'03. Insumos'!A:D,2,0) -> Consultoria Saúde e Segurança do Trabalho | F31: FAT DIRETO | G31: =VLOOKUP(D31,'03. Insumos'!A:F,3,0) -> vb | H31: 2200 | I31: =L2 -> 36 | J31: =IFERROR(IF(K31<>0,K31*$K$5,0),0) -> 1 | K31: =IF(A31=0,VLOOKUP(D31,'03. Insumos'!A:F,4,0),"") -> 1 | L31: =H31*J31*I31 -> 79200 | M31: =L31/$L$7 -> 0.0048089238 | O31: =IF(I31<>0,I31*H31*K31,) -> 79200 | R31: =IF(J31<>0,J31/1.03-K31,0) -> -0.029126214
A32: =LEN(C32) -> 0 | D32: 01.01.2605 | E32: =VLOOKUP(D32,'03. Insumos'!A:D,2,0) -> Consultoria de Impermeabilização | F32: FAT DIRETO | G32: =VLOOKUP(D32,'03. Insumos'!A:F,3,0) -> vb | H32: 980 | J32: =IFERROR(IF(K32<>0,K32*$K$5,0),0) -> 1 | K32: =IF(A32=0,VLOOKUP(D32,'03. Insumos'!A:F,4,0),"") -> 1 | L32: =H32*J32*I32 -> 0 | M32: =L32/$L$7 -> 0 | O32: =IF(I32<>0,I32*H32*K32,) -> 0 | R32: =IF(J32<>0,J32/1.03-K32,0) -> -0.029126214
A33: =LEN(C33) -> 0 | D33: 01.01.3322 | E33: =VLOOKUP(D33,'03. Insumos'!A:D,2,0) -> Consultoria de Instalações | F33: FAT DIRETO | G33: =VLOOKUP(D33,'03. Insumos'!A:F,3,0) -> vb | H33: 6000 | J33: =IFERROR(IF(K33<>0,K33*$K$5,0),0) -> 1 | K33: =IF(A33=0,VLOOKUP(D33,'03. Insumos'!A:F,4,0),"") -> 1 | L33: =H33*J33*I33 -> 0 | M33: =L33/$L$7 -> 0 | O33: =IF(I33<>0,I33*H33*K33,) -> 0 | R33: =IF(J33<>0,J33/1.03-K33,0) -> -0.029126214
A34: =LEN(C34) -> 0 | D34: 01.01.3207 | E34: =VLOOKUP(D34,'03. Insumos'!A:D,2,0) -> Consultoria Fiscal | F34: FAT DIRETO | G34: =VLOOKUP(D34,'03. Insumos'!A:F,3,0) -> mês | I34: 1 | J34: =IFERROR(IF(K34<>0,K34*$K$5,0),0) -> 3500 | K34: =IF(A34=0,VLOOKUP(D34,'03. Insumos'!A:F,4,0),"") -> 3500 | L34: =H34*J34*I34 -> 0 | M34: =L34/$L$7 -> 0 | O34: =IF(I34<>0,I34*H34*K34,) -> 0 | R34: =IF(J34<>0,J34/1.03-K34,0) -> -101.94175
A35: =LEN(C35) -> 0 | D35: 01.01.3010 | E35: =VLOOKUP(D35,'03. Insumos'!A:D,2,0) -> Consultoria de Planejamento e Orçamento da Obra | F35: FAT DIRETO | G35: =VLOOKUP(D35,'03. Insumos'!A:F,3,0) -> mês | H35: 1 | I35: =L2 -> 36 | J35: =IFERROR(IF(K35<>0,K35*$K$5,0),0) -> 2200 | K35: =IF(A35=0,VLOOKUP(D35,'03. Insumos'!A:F,4,0),"") -> 2200 | L35: =H35*J35*I35 -> 79200 | M35: =L35/$L$7 -> 0.0048089238 | O35: =IF(I35<>0,I35*H35*K35,) -> 79200 | R35: =IF(J35<>0,J35/1.03-K35,0) -> -64.07767
A36: =LEN(C36) -> 6 | C36: 01.2.3 | D36: Consultoria de Planejamento e Orçamento da Obra | K36: =IF(A36=0,VLOOKUP(D36,'03. Insumos'!A:F,4,0),"") | L36: =SUM(L37) -> 0 | M36: =L36/$L$7 -> 0 | R36: =IF(J36<>0,J36/1.03-K36,0) -> 0
A37: =LEN(C37) -> 0 | D37: 01.01.3010 | E37: =VLOOKUP(D37,'03. Insumos'!A:D,2,0) -> Consultoria de Planejamento e Orçamento da Obra | F37: FAT DIRETO | G37: =VLOOKUP(D37,'03. Insumos'!A:F,3,0) -> mês | H37: 1 | J37: 3500 | K37: =IF(A37=0,VLOOKUP(D37,'03. Insumos'!A:F,4,0),"") -> 2200 | L37: =H37*J37*I37 -> 0 | M37: =L37/$L$7 -> 0 | O37: =IF(I37<>0,I37*H37*K37,) -> 0 | R37: =IF(J37<>0,J37/1.03-K37,0) -> 1198.0583
A38: =LEN(C38) -> 6 | C38: 01.2.4 | D38: Sondagem - Custo Incorporação | K38: =IF(A38=0,VLOOKUP(D38,'03. Insumos'!A:F,4,0),"") | L38: =SUM(L39:L39) -> 0 | M38: =L38/$L$7 -> 0 | R38: =IF(J38<>0,J38/1.03-K38,0) -> 0
A39: =LEN(C39) -> 0 | D39: 01.01.2613 | E39: =VLOOKUP(D39,'03. Insumos'!A:D,2,0) -> Execução de Sondagem | F39: FAT DIRETO | G39: =VLOOKUP(D39,'03. Insumos'!A:F,3,0) -> vb | J39: =IFERROR(IF(K39<>0,K39*$K$5,0),0) -> 1 | K39: =IF(A39=0,VLOOKUP(D39,'03. Insumos'!A:F,4,0),"") -> 1 | L39: =H39*J39*I39 -> 0 | M39: =L39/$L$7 -> 0 | O39: =IF(I39<>0,I39*H39*K39,) -> 0 | R39: =IF(J39<>0,J39/1.03-K39,0) -> -0.029126214
A40: =LEN(C40) -> 6 | C40: 01.2.5 | D40: Manual do Proprietário | K40: =IF(A40=0,VLOOKUP(D40,'03. Insumos'!A:F,4,0),"") | L40: =SUM(L41:L41) -> 15000 | M40: =L40/$L$7 -> 0.00091078102 | R40: =IF(J40<>0,J40/1.03-K40,0) -> 0
A41: =LEN(C41) -> 0 | D41: 01.01.3048 | E41: =VLOOKUP(D41,'03. Insumos'!A:D,2,0) -> Manual do Proprietário | F41: FAT DIRETO | G41: =VLOOKUP(D41,'03. Insumos'!A:F,3,0) -> vb | H41: 15000 | I41: 1 | J41: 1 | K41: =IF(A41=0,VLOOKUP(D41,'03. Insumos'!A:F,4,0),"") -> 1 | L41: =H41*J41*I41 -> 15000 | M41: =L41/$L$7 -> 0.00091078102 | O41: =IF(I41<>0,I41*H41*K41,) -> 15000 | R41: =IF(J41<>0,J41/1.03-K41,0) -> -0.029126214
...

Sheet 03. Insumos
A2: TABELA DE INSUMOS
A3: CÓDIGO | B3: DESCRIÇÃO | C3: UNIDADE | D3: PREÇO | E3: OBS | F3: DATA
A4: 01.01.0001 | B4: Placa de Obra | C4: vb | D4: 1 | E4: Valor Estimado | F4: 42878
A5: 01.01.0002 | B5: Ensaio de compressão simples | C5: vb | D5: 2000 | E5: Valor Estimado | F5: 42761 | G5: 1.02
A6: 01.01.0003 | B6: Módulo de deformação | C6: vb | D6: 2000 | E6: Valor Estimado | F6: 42761
A7: 01.01.0004 | B7: Módulo de elasticidade | C7: vb | D7: 2000 | E7: Valor Estimado | F7: 42761
A8: 01.01.0005 | B8: Consultoria Estrutura | C8: mês | D8: 3000 | F8: 43766
A9: 01.01.0006 | B9: Levantamento Topográfico Planialtimétrico | C9: uni | D9: 2600 | E9: Toptec | F9: 42761
A10: 01.01.0007 | B10: Madeiramento em Telhado a ser feito | C10: m | D10: =(((((55.85+8.74+10.21)*1.3)*1.03)/1.03)*1.02)/1.02 -> 97.24 | E10: Sco | F10: 43754
A11: 01.01.0008 | B11: Caibro quadrado 5x5x300cm | C11: uni | D11: 20 | E11: Preço Leroy Merlin | F11: 42760
A12: 01.01.0009 | B12: Caibro 5x2,5cm | C12: uni | D12: 12 | E12: Preço Leroy Merlin | F12: 42760
A13: 01.01.0010 | B13: Madeirite | C13: uni | D13: 62 | E13: Preço Comprado Xian | F13: 42760
A14: 01.01.0011 | B14: Malha de aço 10x10cm 2x3m | C14: uni | D14: 60 | E14: Preço Leroy Merlin | F14: 42760
A15: 01.01.0012 | B15: Projeto, Ampliação em Estrutura Metálica, Reforço de Paredes internas | C15: vb | D15: =((((90600+17000)*1.03)/1.03)*1.02)/1.02 -> 107600 | E15: D & G Serviços de Engenharia / Romana - 17000 correção de valor | F15: 43752
A16: 01.01.0013 | B16: Bombeamento de concreto - até 40m³ | C16: dia | D16: 2400 | E16: Supermix | F16: 45383
A17: 01.01.0014 | B17: Bombeamento de concreto - acima 40m³ | C17: m² | D17: 65 | E17: Supermix | F17: 45383
A18: 01.01.0015 | B18: Mesa de escritório | C18: uni | D18: 150 | E18: Preço Comprado Xian | F18: 42760
A19: 01.01.0016 | B19: Cadeira de escritório simples | C19: uni | D19: 100 | E19: Valor Estimado | F19: 42760
A20: 01.01.0017 | B20: Estante de aço | C20: uni | D20: 400 | E20: Valor Estimado | F20: 42760
A21: 01.01.0018 | B21: Ar condicionado | C21: uni | D21: 1500 | E21: Valor Estimado | F21: 42760
A22: 01.01.0019 | B22: Bebedouro de aço | C22: mês | D22: 400 | E22: Preço Comprado Xian | F22: 42760
A23: 01.01.0020 | B23: Kit Primeiros Socorros | C23: uni | D23: 100 | E23: Valor Estimado | F23: 42760
A24: 01.01.0021 | B24: Cafeteira | C24: uni | D24: 100 | E24: Valor Estimado | F24: 42760
A25: 01.01.0022 | B25: Computador | C25: uni | D25: 1000 | E25: Valor Estimado | F25: 42760
A26: 01.01.0023 | B26: Compra de Impressora A3 | C26: uni | D26: 2500 | E26: Valor Estimado | F26: 42760
A27: 01.01.0024 | B27: Cartuchos de impressora | C27: mês | D27: 300 | E27: Valor Estimado | F27: 42760
A28: 01.01.0025 | B28: Extintor de Pó Químico 4kg | C28: uni | D28: =((((4*135)*1.03)/1.03)*1.02)/1.02 -> 540 | E28: Compra Meet | F28: 44118
A29: 01.01.0026 | B29: Extintor CO2 4Kg | C29: uni | D29: 370 | E29: Compra Meet | F29: 44118
A30: 01.01.0027 | B30: EPI EVENTUAL | C30: mês | D30: 300 | E30: Valor Estimado | F30: 42760
A31: 01.01.0028 | B31: Acompanhamento Mensal Tec. Seg. | C31: mês | D31: 1000 | E31: Brascipa | F31: 43040
A32: 01.01.0029 | B32: Bandeja primária | C32: m | D32: 100 | E32: Preço Material | F32: 42760
A33: 01.01.0030 | B33: Proteção periférica - locação | C33: m | D33: 5.3 | E33: Scora | F33: 42878
A34: 01.01.0031 | B34: Munk Locação | C34: dia | D34: 800 | E34: Local | F34: 42760
A35: 01.01.0032 | B35: Velox Locação | C35: mês | D35: 290 | E35: Valor Estimado | F35: 42760
A36: 01.01.0033 | B36: Frete Velox Ida e Volta | C36: uni | D36: 180 | E36: Valor Estimado | F36: 42760
A37: 01.01.0034 | B37: Escavadeira Locação | C37: mês | D37: =((((115*8*22)*1.03)/1.03)*1.02)/1.02 -> 20240 | E37: Transmater | F37: 42878
A38: 01.01.0035 | B38: Frete Escavadeira Ida e Volta | C38: uni | D38: 1400 | E38: Transmater | F38: 42878
A39: 01.01.0036 | B39: Retroescavadeira Locação | C39: mês | D39: 32000 | E39: Transmater | F39: 42878
A40: 01.01.0037 | B40: Frete Retroescavadeira Ida e Volta | C40: uni | D40: 1400 | E40: Transmater | F40: 42878
A41: 01.01.0038 | B41: Locação de máquinas geral | C41: mês | D41: 850 | E41: Valor Estimado | F41: 42760
...

Sheet 04. Histograma MO
B2: HISTOGRAMA DE MÃO DE OBRA | CF2: PRAZO (meses)
CF3: ='02. Orçamento'!L2 -> 36
A6: EQUIPE TÉCNICA E ADMINISTRATIVA DE OBRA
A7: FUNÇÃO | B7: MÊS 1 | D7: MÊS 2 | F7: MÊS 3 | H7: MÊS 4 | J7: MÊS 5 | L7: MÊS 6 | N7: MÊS 7 | P7: MÊS 8 | R7: MÊS 9 | T7: MÊS 10 | V7: MÊS 11 | X7: MÊS 12 | Z7: MÊS 13 | AB7: MÊS 14 | AD7: MÊS 15 | AF7: MÊS 16 | AH7: MÊS 17 | AJ7: MÊS 18 | AL7: MÊS 19 | AN7: MÊS 20 | AP7: MÊS 21 | AR7: MÊS 22 | AT7: MÊS 23 | AV7: MÊS 24 | AX7: MÊS 25 | AZ7: MÊS 26 | BB7: MÊS 27 | BD7: MÊS 28 | BF7: MÊS 29 | BH7: MÊS 30 | BJ7: MÊS 31 | BL7: MÊS 32 | BN7: MÊS 33 | BP7: MÊS 34 | BR7: MÊS 35 | BT7: MÊS 36 | BV7: MÊS 37 | BX7: MÊS 38 | BZ7: MÊS 39 | CB7: MÊS 40 | CD7: Total | CE7: R$ | CF7: R$ Total
B8: Qtd | C8: HE | D8: Qtd | E8: HE | F8: Qtd | G8: HE | H8: Qtd | I8: HE | J8: Qtd | K8: HE | L8: Qtd | M8: HE | N8: Qtd | O8: HE | P8: Qtd | Q8: HE | R8: Qtd | S8: HE | T8: Qtd | U8: HE | V8: Qtd | W8: HE | X8: Qtd | Y8: HE | Z8: Qtd | AA8: HE | AB8: Qtd | AC8: HE | AD8: Qtd | AE8: HE | AF8: Qtd | AG8: HE | AH8: Qtd | AI8: HE | AJ8: Qtd | AK8: HE | AL8: Qtd | AM8: HE | AN8: Qtd | AO8: HE | AP8: Qtd | AQ8: HE | AR8: Qtd | AS8: HE | AT8: Qtd | AU8: HE | AV8: Qtd | AW8: HE | AX8: Qtd | AY8: HE | AZ8: Qtd | BA8: HE | BB8: Qtd | BC8: HE | BD8: Qtd | BE8: HE | BF8: Qtd | BG8: HE | BH8: Qtd | BI8: HE | BJ8: Qtd | BK8: HE | BL8: Qtd | BM8: HE | BN8: Qtd | BO8: HE | BP8: Qtd | BQ8: HE | BR8: Qtd | BS8: HE | BT8: Qtd | BU8: HE | BV8: Qtd | BW8: HE | BX8: Qtd | BY8: HE | BZ8: Qtd | CA8: HE | CB8: Qtd | CC8: HE
A9: REGIME PJ | CF9: =SUM(CF10:CF15) -> 320400
